Workbook

Sheet Anotações
B2: Deal com A Gazeta
B3: Conselho Consultivo | C3: Quais pessoas (Dudu, Omar, Simone?, Patrick?, Marcus Buaiz?, Angelo?, Fere?, Ulisses?, ), o que esperamos, qual remuneracao (% baixo ou pagar(quanto?)) , área (marketing, tech), qual frequencia (mensal/trimestral) etc
B4: Partnership de ações (tentar definir)
B5: Ações internas (eventos colaborador SG&A)
B6: Quais ferramentas precisamos desenvolver
B7: Produtos&Serviços gerais
B9: Fazer painel de iniciativas e Projetos | C9: https://docs.google.com/document/d/1Bd9xdiEdrcTYg6vKJGJvyknFmdaPA3eUgVTLtH2r8Kg/edit?tab=t.0
B11: Fechar OKR Trimestre e KPIs de acompanhamento
B13: Participacoes em outras empresas e ventures
B14: Hugz
B15: Marketing de Rochas
B16: Deal com Maely
B17: Capex outras iniciativas
B18: TurbOOH | C18: CAPEX infinito, Payback esperado 4 meses,
B20: Comites:
B21: Produto*
B22: Gente e Gestao
B23: Financeiro
B24: Vendas
B25: Content
B27: Premiações
B28: Final do Ano | C28: 30% Bonus | D28: 70% Dividendo | E28: BATER ISSO
B29: Spot Bonus | C29: Figurativo para os destaques
B30: Mensal | C30: Caju turbinado | D30: cafe da manha | E30: almoco equipe etc
B32: Distribuição = Caixa inicial + Geração de Caixa periodo - SALDO MINIMO CAIXA
B33: Poítica de 1x caixa para 2026 | D33: Visão de DRE
B36: Caixa | C36: 1700000 | I36: Mudanças
B37: Cap Table | C37: 0.7 | D37: Dividendo | E37: Salários | F37: Bonus | I37: Bônus no inicio do ano atrelado a geração de caixa
B38: Rodrigo | C38: 0.386 | D38: =C38*$C$37*$C$36 -> 459340 | E38: =25000*12 -> 300000 | F38: =E48 -> 38250 | G38: =E38+D38+F38 -> 797590 | I38: Heads - 30%
B39: Andre Musso | C39: 0.28 | D39: =C39*$C$37*$C$36 -> 333200 | E39: =25000*12 -> 300000 | F39: =E47 -> 38250 | G39: =E39+D39+F39 -> 671450 | I39: Especialistas (15 -20 pessoas) - 30%
B40: Victor Peixoto | C40: 0.284 | D40: =C40*$C$37*$C$36 -> 337960 | E40: =30000*12 -> 360000 | F40: =E44 -> 51000 | G40: =E40+D40+F40 -> 748960 | I40: Executivos - 40%
B41: Pool | C41: 0.05 | D41: =C41*$C$37*$C$36 -> 59500
I42: Condições
C43: Time | D43: 0.3 | E43: =C36*D43 -> 510000 | I43: <10k - Pagamento em 3x
B44: Victor | C44: CEO | D44: 0.1 | E44: =D44*$D$43*$C$36 -> 51000 | I44: 10k - Pagamento em 6x
B45: Rafael | C45: COO | D45: 0.075 | E45: =D45*$D$43*$C$36 -> 38250 | I45: Se sair da companhia, perde o bônus a receber
B46: João | C46: CRO | D46: 0.075 | E46: =D46*$D$43*$C$36 -> 38250
B47: André | C47: CIO | D47: 0.075 | E47: =D47*$D$43*$C$36 -> 38250 | I47: Spot bonus
B48: Rodrigo | C48: CNBO | D48: 0.075 | E48: =D48*$D$43*$C$36 -> 38250 | I48: Será uma premiação individual reconhecida pelos fundadores
B49: Lucas, Roberto, Glauber, Ismael, Padrão, Breno, Pedro, Karol | C49: Heads | D49: 0.3 | E49: =D49*$D$43*$C$36 -> 153000 | F49: =E49/10 -> 15300 | G49: Todos podem ganharar? Qual critério? | I49: Premios surpresas
...

Sheet Overview
B2: Trimestre | C2: 1 Trimestre | F2: 2 Trimestre | I2: 3 Trimestre | L2: 4 Trimestre | R2: 1 Trimestre
C3: Janeiro | D3: Feveiro | E3: Março | F3: Abril | G3: Maio | H3: Junho | I3: Julho | J3: Agosto | K3: Setembro | L3: Outubro | M3: Novembro | N3: Dezembro | O3: Total | R3: Inadimpência | S3: 0.06
B4: (+) MRR Ativo | C4: =Revenue!D5 -> 1156850 | D4: =Revenue!E5 -> 1267733.5 | E4: =Revenue!F5 -> 1368637.5 | F4: =Revenue!G5 -> 1485460.1 | G4: =Revenue!H5 -> 1591768.7 | H4: =Revenue!I5 -> 1688509.5 | I4: =Revenue!J5 -> 1806543.7 | J4: =Revenue!K5 -> 1913954.7 | ... N4: =Revenue!O5 -> 2337387.9 | O4: =sum(C4:N4) -> 20998078
B5: (+) Receita Pontual | C5: =Revenue!D37 -> 240000 | D5: =Revenue!E37 -> 280000 | E5: =Revenue!F37 -> 270000 | F5: =Revenue!G37 -> 288333.33 | G5: =Revenue!H37 -> 306666.67 | H5: =Revenue!I37 -> 325000 | I5: =Revenue!J37 -> 343333.33 | J5: =Revenue!K37 -> 361666.67 | ... N5: =Revenue!O37 -> 435000 | O5: =sum(C5:N5) -> 4045000 | R5: 2 Trimestre
B6: (+) Outras Receitas | C6: ='Outras Receitas'!C15 -> 20766.667 | D6: ='Outras Receitas'!D15 -> 60408 | E6: ='Outras Receitas'!E15 -> 25626.667 | F6: ='Outras Receitas'!F15 -> 43076.667 | G6: ='Outras Receitas'!G15 -> 90096.667 | H6: ='Outras Receitas'!H15 -> 48783.333 | I6: ='Outras Receitas'!I15 -> 85573.333 | J6: ='Outras Receitas'!J15 -> 135713.33 | ... N6: ='Outras Receitas'!N15 -> 137006.67 | O6: =sum(C6:N6) -> 1040111.3 | R6: Inadimpência | S6: 0.06
B7: (=) Receita Total Faturavel | C7: =C4+C5+C6 -> 1417616.7 | D7: =D4+D5+D6 -> 1608141.5 | E7: =E4+E5+E6 -> 1664264.2 | F7: =F4+F5+F6 -> 1816870.1 | G7: =G4+G5+G6 -> 1988532 | H7: =H4+H5+H6 -> 2062292.9 | I7: =I4+I5+I6 -> 2235450.3 | J7: =J4+J5+J6 -> 2411334.7 | ... O7: =O4+O5+O6 -> 26083189
B8: (-) Inadimplência | C8: =C7*$S$3 -> 85057 | D8: =D7*$S$3 -> 96488.49 | E8: =E7*$S$3 -> 99855.849 | F8: =F7*$S$6 -> 109012.21 | G8: =G7*$S$6 -> 119311.92 | H8: =H7*$S$6 -> 123737.57 | I8: =I7*$S$9 -> 134127.02 | J8: =J7*$S$9 -> 144680.08 | K8: =K7*$S$9 -> 148244.73 | L8: =L7*$S$12 -> 159959.15 | M8: =M7*$S$12 -> 169953.67 | N8: =N7*$S$12 -> 174563.67 | O8: =sum(C8:N8) -> 1564991.4 | P8: =O8/$O$7 -> 0.06 | R8: 3 Trimestre
B9: (-) Impostos Sob Receita | C9: ='Tributário'!F11+'Tributário'!F12+'Tributário'!F13 -> 133132.3 | D9: ='Tributário'!G11+'Tributário'!G12+'Tributário'!G13 -> 150146.17 | E9: ='Tributário'!H11+'Tributário'!H12+'Tributário'!H13 -> 155157.92 | F9: ='Tributário'!I11+'Tributário'!I12+'Tributário'!I13 -> 170420.41 | G9: ='Tributário'!J11+'Tributário'!J12+'Tributário'!J13 -> 185749.82 | H9: ='Tributário'!K11+'Tributário'!K12+'Tributário'!K13 -> 192336.66 | I9: ='Tributário'!L11+'Tributário'!L12+'Tributário'!L13 -> 207799.63 | J9: ='Tributário'!M11+'Tributário'!M12+'Tributário'!M13 -> 223506.1 | ... N9: ='Tributário'!Q11+'Tributário'!Q12+'Tributário'!Q13 -> 267982.85 | O9: =sum(C9:N9) -> 2422411.4 | P9: =O9/$O$7 -> 0.092872516 | R9: Inadimpência | S9: 0.06
B10: (=) Receita Líquida | C10: =C7-C8-C9 -> 1199427.4 | D10: =D7-D8-D9 -> 1361506.8 | E10: =E7-E8-E9 -> 1409250.4 | F10: =F7-F8-F9 -> 1537437.5 | G10: =G7-G8-G9 -> 1683470.3 | H10: =H7-H8-H9 -> 1746218.6 | I10: =I7-I8-I9 -> 1893523.7 | J10: =J7-J8-J9 -> 2043148.5 | ... N10: =N7-N8-N9 -> 2466848 | O10: =sum(C10:N10) -> 22095787 | Q10: =O10/$O$7 -> 0.84712748
B11: (-) CSV - Salários | C11: =CSV!D4 -> 345754.4 | D11: =CSV!E4 -> 380706.3 | E11: =CSV!F4 -> 399437.54 | F11: =CSV!G4 -> 465597.96 | G11: =CSV!H4 -> 488400.64 | H11: =CSV!I4 -> 495996.08 | I11: =CSV!J4 -> 557632.94 | J11: =CSV!K4 -> 583914.17 | ... N11: =CSV!O4 -> 687435.48 | O11: =sum(C11:N11) -> 6314099.1 | P11: =O11/$O$7 -> 0.24207542 | R11: 4 Trimestre
B12: (-) CSV - Benefício | C12: =(CSV!D7*400) -> 29200 | D12: =(CSV!E7*400) -> 32000 | E12: =(CSV!F7*400) -> 33200 | F12: =(CSV!G7*400) -> 37200 | G12: =(CSV!H7*400) -> 38800 | H12: =(CSV!I7*400) -> 39200 | I12: =(CSV!J7*400) -> 41600 | J12: =(CSV!K7*400) -> 43200 | ... N12: =(CSV!O7*400) -> 48800 | O12: =sum(C12:N12) -> 481200 | P12: =O12/$O$7 -> 0.018448664 | R12: Inadimpência | S12: 0.06
B13: (-) CSV - Stack Tecnologia | C13: ='SG&A'!C42 -> 41540 | D13: ='SG&A'!D42 -> 41932 | E13: ='SG&A'!E42 -> 42177 | F13: ='SG&A'!F42 -> 44635 | G13: ='SG&A'!G42 -> 44831 | H13: ='SG&A'!H42 -> 44929 | I13: ='SG&A'!I42 -> 62293 | J13: ='SG&A'!J42 -> 47538 | ... N13: ='SG&A'!N42 -> 49441 | O13: =sum(C13:N13) -> 565344 | P13: =O13/$O$7 -> 0.02167465
B14: (=) Margem Bruta | C14: =C10-C11-C12-C13 -> 782932.97 | D14: =D10-D11-D12-D13 -> 906868.54 | E14: =E10-E11-E12-E13 -> 934435.85 | F14: =F10-F11-F12-F13 -> 990004.53 | G14: =G10-G11-G12-G13 -> 1111438.6 | H14: =H10-H11-H12-H13 -> 1166093.5 | I14: =I10-I11-I12-I13 -> 1231997.7 | J14: =J10-J11-J12-J13 -> 1368496.4 | ... N14: =N10-N11-N12-N13 -> 1681171.6 | O14: =sum(C14:N14) -> 14735144 | Q14: =O14/$O$7 -> 0.56492875
B15: (-) CAC | C15: =CAC!C6 -> 262495.71 | D15: =CAC!D6 -> 285895.71 | E15: =CAC!E6 -> 311895.71 | F15: =CAC!F6 -> 337573.77 | G15: =CAC!G6 -> 422573.77 | H15: =CAC!H6 -> 362573.77 | I15: =CAC!I6 -> 453925.18 | J15: =CAC!J6 -> 371925.18 | ... N15: =CAC!N6 -> 428776.58 | O15: =sum(C15:N15) -> 4449113.7 | P15: =O15/$O$7 -> 0.17057399
B16: (-) SG&A | C16: ='SG&A'!C6-C12-C13 -> 227706 | D16: ='SG&A'!D6-D12-D13 -> 218106 | E16: ='SG&A'!E6-E12-E13 -> 218906 | F16: ='SG&A'!F6-F12-F13 -> 210206 | G16: ='SG&A'!G6-G12-G13 -> 211206 | H16: ='SG&A'!H6-H12-H13 -> 215606 | I16: ='SG&A'!I6-I12-I13 -> 213606 | J16: ='SG&A'!J6-J12-J13 -> 214006 | ... N16: ='SG&A'!N6-N12-N13 -> 265606 | O16: =sum(C16:N16) -> 2688672 | P16: =O16/$O$7 -> 0.10308065
B17: (-) Bônus | C17: 54000 | D17: 23000 | E17: 23000
B18: (=) EBITDA | C18: =C14-C15-C16-C17 -> 238731.26 | D18: =D14-D15-D16-D17 -> 379866.83 | E18: =E14-E15-E16-E17 -> 380634.14 | F18: =F14-F15-F16-F17 -> 442224.76 | G18: =G14-G15-G16-G17 -> 477658.87 | H18: =H14-H15-H16-H17 -> 587913.76 | I18: =I14-I15-I16-I17 -> 564466.57 | J18: =J14-J15-J16-J17 -> 782565.2 | ... O18: =O14-O15-O16-O17 -> 7597357.9 | Q18: =O18/$O$7 -> 0.29127411
B19: (-) IR + CSLL + ICMS + DIFALS | C19: ='Tributário'!F14 -> 99528.628 | D19: ='Tributário'!G14 -> 136974.72 | E19: ='Tributário'!H14 -> 137235.61 | F19: ='Tributário'!I14 -> 150356.42 | G19: ='Tributário'!J14 -> 162404.02 | H19: ='Tributário'!K14 -> 199890.68 | I19: ='Tributário'!L14 -> 191918.63 | J19: ='Tributário'!M14 -> 266072.17 | ... N19: ='Tributário'!Q14 -> 335508.25 | O19: =sum(C19:N19) -> 2583101.7 | P19: =O19/$O$7 -> 0.099033199
B20: (-) CAPEX | C20: ='CAPEX e Giro'!D5 -> 35000 | D20: ='CAPEX e Giro'!E5 -> 35000 | E20: ='CAPEX e Giro'!F5 -> 35000 | F20: ='CAPEX e Giro'!G5 -> 35000 | G20: ='CAPEX e Giro'!H5 -> 35000 | H20: ='CAPEX e Giro'!I5 -> 35000 | I20: ='CAPEX e Giro'!J5 -> 35000 | J20: ='CAPEX e Giro'!K5 -> 35000 | ... N20: ='CAPEX e Giro'!O5 -> 35000 | O20: =sum(C20:N20) -> 420000 | P20: =O20/$O$7 -> 0.016102325
B21: (=) Geração de Caixa | C21: =C18-C19-C20 -> 104202.63 | D21: =D18-D19-D20 -> 207892.11 | E21: =E18-E19-E20 -> 208398.53 | F21: =F18-F19-F20 -> 256868.34 | G21: =G18-G19-G20 -> 280254.86 | H21: =H18-H19-H20 -> 353023.08 | I21: =I18-I19-I20 -> 337547.94 | J21: =J18-J19-J20 -> 481493.03 | ... O21: =O18-O19-O20 -> 4594256.2 | P21: =O21/$O$7 -> 0.17613859
B22: (%) Margem Geração | C22: =C21/C7 -> 0.073505506 | D22: =D21/D7 -> 0.12927476 | E22: =E21/E7 -> 0.12521962 | F22: =F21/F7 -> 0.14137958 | G22: =G21/G7 -> 0.14093555 | H22: =H21/H7 -> 0.1711799 | I22: =I21/I7 -> 0.15099773 | J22: =J21/J7 -> 0.19967905 | ... N22: =N21/N7 -> 0.21182439
B24: Métricas Gerais
B25: Receita Total | C25: =C7-C8 -> 1332559.7 | D25: =D7-D8 -> 1511653 | E25: =E7-E8 -> 1564408.3 | F25: =F7-F8 -> 1707857.9 | G25: =G7-G8 -> 1869220.1 | H25: =H7-H8 -> 1938555.3 | I25: =I7-I8 -> 2101323.3 | J25: =J7-J8 -> 2266654.6 | ... N25: =N7-N8 -> 2734830.9
B26: Despesa Total | C26: =C9+C11+C15+C16+C19+C20+C12+C13+C17 -> 1228357 | D26: =D9+D11+D15+D16+D19+D20+D12+D13+D17 -> 1303760.9 | E26: =E9+E11+E15+E16+E19+E20+E12+E13+E17 -> 1356009.8 | F26: =F9+F11+F15+F16+F19+F20+F12+F13+F17 -> 1450989.6 | G26: =G9+G11+G15+G16+G19+G20+G12+G13+G17 -> 1588965.3 | H26: =H9+H11+H15+H16+H19+H20+H12+H13+H17 -> 1585532.2 | I26: =I9+I11+I15+I16+I19+I20+I12+I13+I17 -> 1763775.4 | J26: =J9+J11+J15+J16+J19+J20+J12+J13+J17 -> 1785161.6 | ... N26: =N9+N11+N15+N16+N19+N20+N12+N13+N17 -> 2118550.2
B27: Vendas MRR | C27: =CAC!Q7 -> 215000 | D27: =CAC!R7 -> 215000 | E27: =CAC!S7 -> 215000 | F27: =CAC!T7 -> 240000 | G27: =CAC!U7 -> 240000 | H27: =CAC!V7 -> 240000 | I27: =CAC!W7 -> 270000 | J27: =CAC!X7 -> 270000 | ... N27: =CAC!AB7 -> 300000
B28: Vendas Pontual | C28: =CAC!Q38 -> 270000 | D28: =CAC!R38 -> 270000 | E28: =CAC!S38 -> 270000 | F28: =CAC!T38 -> 325000 | G28: =CAC!U38 -> 325000 | H28: =CAC!V38 -> 325000 | I28: =CAC!W38 -> 380000 | J28: =CAC!X38 -> 380000 | ... N28: =CAC!AB38 -> 435000
B29: Numero de Colaboradores | C29: =C42 -> 109 | D29: =D42 -> 117 | E29: =E42 -> 122 | F29: =F42 -> 134 | G29: =G42 -> 138 | H29: =H42 -> 140 | I29: =I42 -> 146 | J29: =J42 -> 151 | ... N29: =N42 -> 168
B30: Receita Cabeça | C30: =C7/C29 -> 13005.657 | D30: =D7/D29 -> 13744.799 | E30: =E7/E29 -> 13641.509 | F30: =F7/F29 -> 13558.732 | G30: =G7/G29 -> 14409.652 | H30: =H7/H29 -> 14730.663 | I30: =I7/I29 -> 15311.304 | J30: =J7/J29 -> 15969.104 | ... N30: =N7/N29 -> 17317.825 | O30: =N30/C30-1 -> 0.33156088
B31: MRR Cabeça | C31: =C4/C29 -> 10613.303 | D31: =D4/D29 -> 10835.329 | E31: =E4/E29 -> 11218.34 | F31: =F4/F29 -> 11085.523 | G31: =G4/G29 -> 11534.556 | H31: =H4/H29 -> 12060.782 | I31: =I4/I29 -> 12373.587 | J31: =J4/J29 -> 12675.197 | ... N31: =N4/N29 -> 13913.023
B32: Numero de Clientes | C32: =C33/1.38 -> 300.66977 | D32: =D33/1.38 -> 330.2517 | E32: =E33/1.38 -> 352.00541 | F32: =F33/1.38 -> 377.78291 | G32: =G33/1.38 -> 402.43492 | H32: =H33/1.38 -> 423.7875 | I32: =I33/1.38 -> 449.22341 | J32: =J33/1.38 -> 474.6896 | K32: =K33/1.37 -> 500.42409 | L32: =L33/1.4 -> 515.46212 | M32: =M33/1.4 -> 541.19276 | N32: =N33/1.4 -> 563.56566
B33: Numero de Contratos | C33: =CSV!C12+CSV!C85+CSV!C141+CSV!C202+CSV!C225+CAC!Q42+CAC!Q47+CAC!Q52+CAC!Q57+CAC!Q62+CAC!Q67 -> 414.92429 | D33: =CSV!D12+CSV!D85+CSV!D141+CSV!D202+CSV!D225+CAC!R42+CAC!R47+CAC!R52+CAC!R57+CAC!R62+CAC!R67 -> 455.74735 | E33: =CSV!E12+CSV!E85+CSV!E141+CSV!E202+CSV!E225+CAC!S42+CAC!S47+CAC!S52+CAC!S57+CAC!S62+CAC!S67 -> 485.76747 | F33: =CSV!F12+CSV!F85+CSV!F141+CSV!F202+CSV!F225+CAC!T42+CAC!T47+CAC!T52+CAC!T57+CAC!T62+CAC!T67 -> 521.34042 | G33: =CSV!G12+CSV!G85+CSV!G141+CSV!G202+CSV!G225+CAC!U42+CAC!U47+CAC!U52+CAC!U57+CAC!U62+CAC!U67 -> 555.36019 | H33: =CSV!H12+CSV!H85+CSV!H141+CSV!H202+CSV!H225+CAC!V42+CAC!V47+CAC!V52+CAC!V57+CAC!V62+CAC!V67 -> 584.82675 | I33: =CSV!I12+CSV!I85+CSV!I141+CSV!I202+CSV!I225+CAC!W42+CAC!W47+CAC!W52+CAC!W57+CAC!W62+CAC!W67 -> 619.9283 | J33: =CSV!J12+CSV!J85+CSV!J141+CSV!J202+CSV!J225+CAC!X42+CAC!X47+CAC!X52+CAC!X57+CAC!X62+CAC!X67 -> 655.07165 | ... N33: =CSV!N12+CSV!N85+CSV!N141+CSV!N202+CSV!N225+CAC!AB42+CAC!AB47+CAC!AB52+CAC!AB57+CAC!AB62+CAC!AB67 -> 788.99192
B34: Ticket Medio Cliente | C34: =C7/C32 -> 4714.8626 | D34: =D7/D32 -> 4869.442 | E34: =E7/E32 -> 4727.9504 | F34: =F7/F32 -> 4809.2967 | G34: =G7/G32 -> 4941.2512 | H34: =H7/H32 -> 4866.3372 | I34: =I7/I32 -> 4976.2552 | J34: =J7/J32 -> 5079.8137 | ... N34: =N7/N32 -> 5162.4766
B35: Ticket Medio Contratos | C35: =C7/C33 -> 3416.5671 | D35: =D7/D33 -> 3528.5811 | E35: =E7/E33 -> 3426.051 | F35: =F7/F33 -> 3484.9976 | G35: =G7/G33 -> 3580.6168 | H35: =H7/H33 -> 3526.3313 | I35: =I7/I33 -> 3605.9821 | J35: =J7/J33 -> 3681.0244 | ... N35: =N7/N33 -> 3687.4833
B36: Churn Mês | C36: =Revenue!D32 -> 104116.5 | D36: =Revenue!E32 -> 114096.01 | E36: =Revenue!F32 -> 123177.37 | F36: =Revenue!G32 -> 133691.41 | G36: =Revenue!H32 -> 143259.18 | H36: =Revenue!I32 -> 151965.86 | I36: =Revenue!J32 -> 162588.93 | J36: =Revenue!K32 -> 172255.93 | ... N36: =Revenue!O32 -> 210364.91
B37: Aliquota Imposto Efetiva | C37: =(C19+C9)/C7 -> 0.16412118 | D37: =(D19+D9)/D7 -> 0.17854206 | E37: =(E19+E9)/E7 -> 0.17568937 | F37: =(F19+F9)/F7 -> 0.17655463 | G37: =(G19+G9)/G7 -> 0.17508083 | H37: =(H19+H9)/H7 -> 0.19018993 | I37: =(I19+I9)/I7 -> 0.17880883 | J37: =(J19+J9)/J7 -> 0.20303207 | ... O37: =(O19+O9)/O7 -> 0.19190571
B38: Geracao de caixa | C38: =C21 -> 104202.63 | D38: =D21 -> 207892.11 | E38: =E21 -> 208398.53 | F38: =F21 -> 256868.34 | G38: =G21 -> 280254.86 | H38: =H21 -> 353023.08 | I38: =I21 -> 337547.94 | J38: =J21 -> 481493.03 | ... N38: =N21 -> 616280.72
B39: Margem de geração | C39: =C22 -> 0.073505506 | D39: =D22 -> 0.12927476 | E39: =E22 -> 0.12521962 | F39: =F22 -> 0.14137958 | G39: =G22 -> 0.14093555 | H39: =H22 -> 0.1711799 | I39: =I22 -> 0.15099773 | J39: =J22 -> 0.19967905 | ... N39: =N22 -> 0.21182439 | O39: =P21 -> 0.17613859
B40: Saldo de Caixa | C40: =535000+C38 -> 639202.63 | D40: =C40+D38 -> 847094.74 | E40: =D40+E38 -> 1055493.3 | F40: =E40+F38 -> 1312361.6 | G40: =F40+G38 -> 1592616.5 | H40: =G40+H38 -> 1945639.5 | I40: =H40+I38 -> 2283187.5 | J40: =I40+J38 -> 2764680.5 | K40: =J40+K38 -> 3260111.3 | ... N40: =M40+N38 -> 5029256.2
B42: Numero de Colaboradores | C42: =CSV!D7+count('SG&A'!C20:C22)+count('SG&A'!C28:C37)+count(CAC!C22:C38)+count(CAC!C44:C59)+count(CAC!C66:C71)+count(CAC!C77:C86) -> 109 | D42: =CSV!E7+count('SG&A'!D20:D22)+count('SG&A'!D28:D37)+count(CAC!D22:D38)+count(CAC!D44:D59)+count(CAC!D66:D71)+count(CAC!D77:D86) -> 117 | E42: =CSV!F7+count('SG&A'!E20:E22)+count('SG&A'!E28:E37)+count(CAC!E22:E38)+count(CAC!E44:E59)+count(CAC!E66:E71)+count(CAC!E77:E86) -> 122 | F42: =CSV!G7+count('SG&A'!F20:F22)+count('SG&A'!F28:F37)+count(CAC!F22:F38)+count(CAC!F44:F59)+count(CAC!F66:F71)+count(CAC!F77:F86) -> 134 | G42: =CSV!H7+count('SG&A'!G20:G22)+count('SG&A'!G28:G37)+count(CAC!G22:G38)+count(CAC!G44:G59)+count(CAC!G66:G71)+count(CAC!G77:G86) -> 138 | H42: =CSV!I7+count('SG&A'!H20:H22)+count('SG&A'!H28:H37)+count(CAC!H22:H38)+count(CAC!H44:H59)+count(CAC!H66:H71)+count(CAC!H77:H86) -> 140 | I42: =CSV!J7+count('SG&A'!I20:I22)+count('SG&A'!I28:I37)+count(CAC!I22:I38)+count(CAC!I44:I59)+count(CAC!I66:I71)+count(CAC!I77:I86) -> 146 | J42: =CSV!K7+count('SG&A'!J20:J22)+count('SG&A'!J28:J37)+count(CAC!J22:J38)+count(CAC!J44:J59)+count(CAC!J66:J71)+count(CAC!J77:J86) -> 151 | ... N42: =CSV!O7+count('SG&A'!N20:N22)+count('SG&A'!N28:N37)+count(CAC!N22:N38)+count(CAC!N44:N59)+count(CAC!N66:N71)+count(CAC!N77:N86) -> 168
B43: Pessoas em CSV | C43: =CSV!D7 -> 73 | D43: =CSV!E7 -> 80 | E43: =CSV!F7 -> 83 | F43: =CSV!G7 -> 93 | G43: =CSV!H7 -> 97 | H43: =CSV!I7 -> 98 | I43: =CSV!J7 -> 104 | J43: =CSV!K7 -> 108 | ... N43: =CSV!O7 -> 122
...

Sheet SG&A
B2: CSV
B3: Trimestre | C3: 1 Trimestre | F3: 2 Trimestre | I3: 3 Trimestre | L3: 4 Trimestre
B4: Mês | C4: Janeiro | D4: Feveiro | E4: Março | F4: Abril | G4: Maio | H4: Junho | I4: Julho | J4: Agosto | K4: Setembro | L4: Outubro | M4: Novembro | N4: Dezembro
B5: Pessoas Totais Commerce (CSV) | C5: =count(C20:C22)+count(C28:C37) -> 12 | D5: =count(D20:D22)+count(D28:D37) -> 12 | E5: =count(E20:E22)+count(E28:E37) -> 12 | F5: =count(F20:F22)+count(F28:F37) -> 11 | G5: =count(G20:G22)+count(G28:G37) -> 11 | H5: =count(H20:H22)+count(H28:H37) -> 12 | I5: =count(I20:I22)+count(I28:I37) -> 12 | J5: =count(J20:J22)+count(J28:J37) -> 12 | ... N5: =count(N20:N22)+count(N28:N37) -> 12
B6: (=) SG&A | C6: =SUM(C7:C14) -> 298446 | D6: =SUM(D7:D14) -> 292038 | E6: =SUM(E7:E14) -> 294283 | F6: =SUM(F7:F14) -> 292041 | G6: =SUM(G7:G14) -> 294837 | H6: =SUM(H7:H14) -> 299735 | I6: =SUM(I7:I14) -> 317499 | J6: =SUM(J7:J14) -> 304744 | ... N6: =SUM(N7:N14) -> 363847
B7: (-) UZK | C7: =C19 -> 80000 | D7: =D19 -> 80000 | E7: =E19 -> 80000 | F7: =F19 -> 80000 | G7: =G19 -> 80000 | H7: =H19 -> 80000 | I7: =I19 -> 80000 | J7: =J19 -> 80000 | ... N7: =N19 -> 80000
B8: (-) Backoffice | C8: =C27 -> 50000 | D8: =D27 -> 46000 | E8: =E27 -> 46000 | F8: =F27 -> 46000 | G8: =G27 -> 47000 | H8: =H27 -> 51000 | I8: =I27 -> 53500 | J8: =J27 -> 53500 | ... N8: =N27 -> 56500
B9: (-) Software | C9: =C42 -> 41540 | D9: =D42 -> 41932 | E9: =E42 -> 42177 | F9: =F42 -> 44635 | G9: =G42 -> 44831 | H9: =H42 -> 44929 | I9: =I42 -> 62293 | J9: =J42 -> 47538 | ... N9: =N42 -> 49441
B10: (-) Ocupação | C10: =C57 -> 34570 | D10: =D57 -> 44570 | E10: =E57 -> 44570 | F10: =F57 -> 34570 | G10: =G57 -> 34570 | H10: =H57 -> 34570 | I10: =I57 -> 29570 | J10: =J57 -> 29570 | ... N10: =N57 -> 29570
B11: (-) Beneficio Caju | C11: ='Overview Old'!C26*400 -> 44000 | D11: ='Overview Old'!D26*400 -> 47200 | E11: ='Overview Old'!E26*400 -> 49200 | F11: ='Overview Old'!F26*400 -> 54000 | G11: ='Overview Old'!G26*400 -> 55600 | H11: ='Overview Old'!H26*400 -> 56400 | I11: ='Overview Old'!I26*400 -> 58800 | J11: ='Overview Old'!J26*400 -> 60800 | K11: ='Overview Old'!K26*400 -> 62000 | L11: ='Overview Old'!L26*500 -> 81000 | M11: ='Overview Old'!M26*500 -> 82500 | N11: ='Overview Old'!N26*500 -> 84500
B12: (-) Premiações | C12: 5000 | D12: 5000 | E12: 5000 | F12: 5000 | G12: 5000 | H12: 5000 | I12: 5000 | J12: 5000 | K12: 5000 | L12: 5000 | M12: 5000 | N12: 5000
B13: (-) Eventos e Brindes Internos | C13: 30000 | D13: 10000 | E13: 10000 | F13: 10000 | G13: 10000 | H13: 10000 | I13: 10000 | J13: 10000 | K13: 10000 | L13: 10000 | M13: 20000 | N13: 40000
B14: (-) Outras despesas | C14: =C68 -> 13336 | D14: =D68 -> 17336 | E14: =E68 -> 17336 | F14: =F68 -> 17836 | G14: =G68 -> 17836 | H14: =H68 -> 17836 | I14: =I68 -> 18336 | J14: =J68 -> 18336 | ... N14: =N68 -> 18836
B16: UZK
B17: Trimestre | C17: 1 Trimestre | F17: 2 Trimestre | I17: 3 Trimestre | L17: 4 Trimestre
B18: Mês | C18: Janeiro | D18: Feveiro | E18: Março | F18: Abril | G18: Maio | H18: Junho | I18: Julho | J18: Agosto | K18: Setembro | L18: Outubro | M18: Novembro | N18: Dezembro
B19: (=) UZK | C19: =SUM(C20:C22) -> 80000 | D19: =SUM(D20:D22) -> 80000 | E19: =SUM(E20:E22) -> 80000 | F19: =SUM(F20:F22) -> 80000 | G19: =SUM(G20:G22) -> 80000 | H19: =SUM(H20:H22) -> 80000 | I19: =SUM(I20:I22) -> 80000 | J19: =SUM(J20:J22) -> 80000 | ... N19: =SUM(N20:N22) -> 80000
B20: (-) Victor Peixoto | C20: 30000 | D20: 30000 | E20: 30000 | F20: 30000 | G20: 30000 | H20: 30000 | I20: 30000 | J20: 30000 | K20: 30000 | L20: 30000 | M20: 30000 | N20: 30000
B21: (-) Rodrigo Queiroz | C21: 25000 | D21: 25000 | E21: 25000 | F21: 25000 | G21: 25000 | H21: 25000 | I21: 25000 | J21: 25000 | K21: 25000 | L21: 25000 | M21: 25000 | N21: 25000
B22: (-) André Musso | C22: 25000 | D22: 25000 | E22: 25000 | F22: 25000 | G22: 25000 | H22: 25000 | I22: 25000 | J22: 25000 | K22: 25000 | L22: 25000 | M22: 25000 | N22: 25000
B24: Backoffice
B25: Trimestre | C25: 1 Trimestre | F25: 2 Trimestre | I25: 3 Trimestre | L25: 4 Trimestre
B26: Mês | C26: Janeiro | D26: Feveiro | E26: Março | F26: Abril | G26: Maio | H26: Junho | I26: Julho | J26: Agosto | K26: Setembro | L26: Outubro | M26: Novembro | N26: Dezembro
B27: (=) Backoffice | C27: =SUM(C28:C37) -> 50000 | D27: =SUM(D28:D37) -> 46000 | E27: =SUM(E28:E37) -> 46000 | F27: =SUM(F28:F37) -> 46000 | G27: =SUM(G28:G37) -> 47000 | H27: =SUM(H28:H37) -> 51000 | I27: =SUM(I28:I37) -> 53500 | J27: =SUM(J28:J37) -> 53500 | ... N27: =SUM(N28:N37) -> 56500
B28: (-) Marlon Carneiro | C28: 7000 | D28: 7000 | E28: 7000 | F28: 7500 | G28: 7500 | H28: 7500 | I28: 7500 | J28: 7500 | K28: 7500 | L28: 8000 | M28: 8000 | N28: 8000
B29: (-) Warley Pablo | C29: 3500 | D29: 3500 | E29: 3500 | F29: 3500 | G29: 3500 | H29: 3500 | I29: 4000 | J29: 4000 | K29: 4000 | L29: 4000 | M29: 4000 | N29: 4000
B30: (-) Eduardo Tonane | C30: 2000 | D30: 2000 | E30: 2000 | F30: 2000 | G30: 3000 | H30: 3000 | I30: 3000 | J30: 3000 | K30: 3000 | L30: 3500 | M30: 3500 | N30: 3500
B31: (-) Karol Tognere | C31: 7000 | D31: 7000 | E31: 7000 | F31: 8000 | G31: 8000 | H31: 8000 | I31: 9000 | J31: 9000 | K31: 9000 | L31: 10000 | M31: 10000 | N31: 10000
B32: (-) Lianca Lopes | C32: 4000 | D32: 4000 | E32: 4000 | F32: 4500 | G32: 4500 | H32: 4500 | I32: 4500 | J32: 4500 | K32: 4500 | L32: 5000 | M32: 5000 | N32: 5000
B33: (-) Caio Massaroni | C33: 7000 | D33: 7000 | E33: 7000 | F33: 7500 | G33: 7500 | H33: 7500 | I33: 8000 | J33: 8000 | K33: 8000 | L33: 8000 | M33: 8000 | N33: 8000
B34: (-) Thiago Folador | C34: 6500 | D34: 6500 | E34: 6500 | F34: 7000 | G34: 7000 | H34: 7000 | I34: 7000 | J34: 7000 | K34: 7000 | L34: 7500 | M34: 7500 | N34: 7500
B35: (-) Julia Viana | C35: 6000 | D35: 6000 | E35: 6000 | F35: 6000 | G35: 6000 | H35: 6000 | I35: 6500 | J35: 6500 | K35: 6500 | L35: 6500 | M35: 6500 | N35: 6500
B36: (-) Marcelus | C36: 7000 | D36: 3000 | E36: 3000
B37: Novo - Contratar | H37: 4000 | I37: 4000 | J37: 4000 | K37: 4000 | L37: 4000 | M37: 4000 | N37: 4000
B39: Software
B40: Trimestre | C40: 1 Trimestre | F40: 2 Trimestre | I40: 3 Trimestre | L40: 4 Trimestre
B41: Mês | C41: Janeiro | D41: Feveiro | E41: Março | F41: Abril | G41: Maio | H41: Junho | I41: Julho | J41: Agosto | K41: Setembro | L41: Outubro | M41: Novembro | N41: Dezembro
B42: (=) Software | C42: =SUM(C43:C52) -> 41540 | D42: =SUM(D43:D52) -> 41932 | E42: =SUM(E43:E52) -> 42177 | F42: =SUM(F43:F52) -> 44635 | G42: =SUM(G43:G52) -> 44831 | H42: =SUM(H43:H52) -> 44929 | I42: =SUM(I43:I52) -> 62293 | J42: =SUM(J43:J52) -> 47538 | ... N42: =SUM(N43:N52) -> 49441
B43: GohighLevel | C43: 5000 | D43: 5000 | E43: 5000 | F43: 5000 | G43: 5000 | H43: 5000 | I43: 5000 | J43: 5000 | K43: 5000 | L43: 5000 | M43: 5000 | N43: 5000
B44: Adobe | C44: 2700 | D44: 2700 | E44: 2700 | F44: 3500 | G44: 3500 | H44: 3500 | I44: 4000 | J44: 4000 | K44: 4000 | L44: 4500 | M44: 4500 | N44: 4500
...

Sheet CSV
C2: Commerce
C3: Mês | D3: Janeiro | E3: Feveiro | F3: Março | G3: Abril | H3: Maio | I3: Junho | J3: Julho | K3: Agosto | L3: Setembro | M3: Outubro | N3: Novembro | O3: Dezembro
C4: CSV Total | D4: =D24+D96+D152+D213+D236+D124+D182+D64+D265+D295+D322+D342 -> 345754.4 | E4: =E24+E96+E152+E213+E236+E124+E182+E64+E265+E295+E322+E342 -> 380706.3 | F4: =F24+F96+F152+F213+F236+F124+F182+F64+F265+F295+F322+F342 -> 399437.54 | G4: =G24+G96+G152+G213+G236+G124+G182+G64+G265+G295+G322+G342 -> 465597.96 | H4: =H24+H96+H152+H213+H236+H124+H182+H64+H265+H295+H322+H342 -> 488400.64 | I4: =I24+I96+I152+I213+I236+I124+I182+I64+I265+I295+I322+I342 -> 495996.08 | J4: =J24+J96+J152+J213+J236+J124+J182+J64+J265+J295+J322+J342 -> 557632.94 | K4: =K24+K96+K152+K213+K236+K124+K182+K64+K265+K295+K322+K342 -> 583914.17 | ... O4: =O24+O96+O152+O213+O236+O124+O182+O64+O265+O295+O322+O342 -> 687435.48
C5: Quantidade de operadores | D5: =D15+D144+D205+D228+D88+D117+D175+D57+D258+D313 -> 67 | E5: =E15+E144+E205+E228+E88+E117+E175+E57+E258+E313 -> 73 | F5: =F15+F144+F205+F228+F88+F117+F175+F57+F258+F313 -> 76 | G5: =G15+G144+G205+G228+G88+G117+G175+G57+G258+G313 -> 86 | H5: =H15+H144+H205+H228+H88+H117+H175+H57+H258+H313 -> 89 | I5: =I15+I144+I205+I228+I88+I117+I175+I57+I258+I313 -> 90 | J5: =J15+J144+J205+J228+J88+J117+J175+J57+J258+J313 -> 95 | K5: =K15+K144+K205+K228+K88+K117+K175+K57+K258+K313 -> 99 | ... O5: =O15+O144+O205+O228+O88+O117+O175+O57+O258+O313 -> 112
C6: Quantidade de Líderes | D6: =D286 -> 6 | E6: =E286 -> 7 | F6: =F286 -> 7 | G6: =G286 -> 7 | H6: =H286 -> 8 | I6: =I286 -> 8 | J6: =J286 -> 9 | K6: =K286 -> 9 | ... O6: =O286 -> 10
C7: Pessoas Totais Commerce (CSV) | D7: =D5+D6 -> 73 | E7: =E5+E6 -> 80 | F7: =F5+F6 -> 83 | G7: =G5+G6 -> 93 | H7: =H5+H6 -> 97 | I7: =I5+I6 -> 98 | J7: =J5+J6 -> 104 | K7: =K5+K6 -> 108 | ... O7: =O5+O6 -> 122
B9: Performance
B10: Mês | C10: Dezembro | D10: Janeiro | E10: Feveiro | F10: Março | G10: Abril | H10: Maio | I10: Junho | J10: Julho | K10: Agosto | L10: Setembro | M10: Outubro | N10: Novembro | O10: Dezembro
B11: MRR Performance | C11: =Revenue!C7 -> 475000 | D11: =Revenue!D7 -> 496750 | E11: =Revenue!E7 -> 516542.5 | F11: =Revenue!F7 -> 534553.68 | G11: =Revenue!G7 -> 558443.84 | H11: =Revenue!H7 -> 580183.9 | I11: =Revenue!I7 -> 599967.35 | J11: =Revenue!J7 -> 626970.29 | ... O11: =Revenue!O7 -> 754263.58 | P11: =SUM(D11:O11) -> 7426334.9
B12: Contratos Performance | C12: =Revenue!C9 -> 176 | D12: =Revenue!D9 -> 181.85009 | E12: =Revenue!E9 -> 187.15183 | F12: =Revenue!F9 -> 191.95774 | G12: =Revenue!G9 -> 198.82868 | H12: =Revenue!H9 -> 205.06444 | I12: =Revenue!I9 -> 210.72459 | J12: =Revenue!J9 -> 218.8743 | ... O12: =Revenue!O9 -> 257.94236
B13: Capacity Contratos | C13: 12 | D13: 12 | E13: 12 | F13: 12 | G13: 12 | H13: 12 | I13: 12 | J13: 12 | K13: 12 | L13: 12 | M13: 12 | N13: 12 | O13: 12
B14: Operadores Necessários | C14: =C12/C13 -> 14.666667 | D14: =D12/D13 -> 15.154174 | E14: =E12/E13 -> 15.595986 | F14: =F12/F13 -> 15.996478 | G14: =G12/G13 -> 16.569057 | H14: =H12/H13 -> 17.088703 | I14: =I12/I13 -> 17.560383 | J14: =J12/J13 -> 18.239525 | ... O14: =O12/O13 -> 21.495197
B15: Operadores Atuais | C15: 15 | D15: =count(D25:D50) -> 17 | E15: =count(E25:E50) -> 19 | F15: =count(F25:F50) -> 20 | G15: =count(G25:G50) -> 20 | H15: =count(H25:H50) -> 21 | I15: =count(I25:I50) -> 21 | J15: =count(J25:J50) -> 22 | K15: =count(K25:K50) -> 22 | ... O15: =count(O25:O50) -> 25
B16: Necessidade de contratar | C16: =C14-C15 -> -0.33333333 | D16: =D14-D15 -> -1.8458256 | E16: =E14-E15 -> -3.4040141 | F16: =F14-F15 -> -4.003522 | G16: =G14-G15 -> -3.4309431 | H16: =H14-H15 -> -3.9112966 | I16: =I14-I15 -> -3.4396175 | J16: =J14-J15 -> -3.7604746 | ... O16: =O14-O15 -> -3.504803
B17: Contratos por gestor | C17: =C12/C15 -> 11.733333 | D17: =D12/D15 -> 10.697064 | E17: =E12/E15 -> 9.8500964 | F17: =F12/F15 -> 9.5978868 | G17: =G12/G15 -> 9.9414342 | H17: =H12/H15 -> 9.7649734 | I17: =I12/I15 -> 10.034504 | J17: =J12/J15 -> 9.948832 | ... O17: =O12/O15 -> 10.317695
B18: MRR por Gestor | C18: =C11/C15 -> 31666.667 | D18: =D11/D15 -> 29220.588 | E18: =E11/E15 -> 27186.447 | F18: =F11/F15 -> 26727.684 | G18: =G11/G15 -> 27922.192 | H18: =H11/H15 -> 27627.805 | I18: =I11/I15 -> 28569.874 | J18: =J11/J15 -> 28498.649 | ... O18: =O11/O15 -> 30170.543
B19: CSV | D19: =(D24+D64)/D11 -> 0.19305486 | E19: =(E24+E64)/E11 -> 0.20598499 | F19: =(F24+F64)/F11 -> 0.21026888 | G19: =(G24+G64)/G11 -> 0.21694214 | H19: =(H24+H64)/H11 -> 0.22001645 | I19: =(I24+I64)/I11 -> 0.21526171 | J19: =(J24+J64)/J11 -> 0.22473154 | K19: =(K24+K64)/K11 -> 0.23313889 | ... O19: =(O24+O64)/O11 -> 0.24215673
C21: Gestor de Performance
C22: Trimestre | D22: 1 Trimestre | G22: 2 Trimestre | J22: 3 Trimestre | M22: 4 Trimestre
C23: Mês | D23: Janeiro | E23: Feveiro | F23: Março | G23: Abril | H23: Maio | I23: Junho | J23: Julho | K23: Agosto | L23: Setembro | M23: Outubro | N23: Novembro | O23: Dezembro | P23: =O24/O11 -> 0.1785185
C24: (=) Gestor de Performance | D24: =SUM(D25:D50) -> 66650 | E24: =SUM(E25:E50) -> 76650 | F24: =SUM(F25:F50) -> 82650 | G24: =SUM(G25:G50) -> 87650 | H24: =SUM(H25:H50) -> 94150 | I24: =SUM(I25:I50) -> 95650 | J24: =SUM(J25:J50) -> 105650 | K24: =SUM(K25:K50) -> 110150 | ... O24: =SUM(O25:O50) -> 134650 | P24: =SUM(D24:O24) -> 1226300
C25: (-) Gabriel Taufner | D25: 2000 | E25: 2000 | F25: 2000 | G25: 2000 | H25: 2500 | I25: 2500 | J25: 2500 | K25: 3000 | L25: 3000 | M25: 3000 | N25: 3500 | O25: 3500
C26: (-) Allan Eduardo | D26: 3000 | E26: 3000 | F26: 3000 | G26: 3500 | H26: 3500 | I26: 3500 | J26: 4000 | K26: 4000 | L26: 4000 | M26: 4500 | N26: 4500 | O26: 4500
C27: (-) Victor Matsushita | D27: 3000 | E27: 3000 | F27: 3500 | G27: 3500 | H27: 3500 | I27: 4000 | J27: 4000 | K27: 4000 | L27: 4500 | M27: 4500 | N27: 4500 | O27: 5000
C28: (-) Gustavo Pires | D28: 4000 | E28: 4000 | F28: 4000 | G28: 4000 | H28: 4500 | I28: 4500 | J28: 4500 | K28: 5000 | L28: 5000 | M28: 5000 | N28: 5000 | O28: 5000
C29: (-) Rayan Coutinho | D29: 4250 | E29: 4250 | F29: 4250 | G29: 4750 | H29: 4750 | I29: 4750 | J29: 5250 | K29: 5250 | L29: 5250 | M29: 5250 | N29: 5750 | O29: 5750
C30: (-) Rafael Avila | D30: 5000 | E30: 5000 | F30: 5000 | G30: 5500 | H30: 5500 | I30: 5500 | J30: 6000 | K30: 6000 | L30: 6000 | M30: 6500 | N30: 6500 | O30: 6500
C31: (-) Thiago Martins | D31: 5000 | E31: 5000 | F31: 5000 | G31: 5000 | H31: 5500 | I31: 5500 | J31: 5500 | K31: 6000 | L31: 6000 | M31: 6000 | N31: 6500 | O31: 6500
C32: (-) Lucas Rosseti | D32: 5000 | E32: 5000 | F32: 5000 | G32: 5500 | H32: 5500 | I32: 5500 | J32: 6000 | K32: 6000 | L32: 6000 | M32: 6500 | N32: 6500 | O32: 6500
C33: (-) Thiago Andrey | D33: 5000 | E33: 5000 | F33: 5000 | G33: 5500 | H33: 5500 | I33: 5500 | J33: 6000 | K33: 6000 | L33: 6000 | M33: 6500 | N33: 6500 | O33: 6500
C34: (-) Victor Arpini | D34: 6000 | E34: 6000 | F34: 6000 | G34: 6000 | H34: 6000 | I34: 6000 | J34: 6000 | K34: 6000 | L34: 6000 | M34: 6500 | N34: 6500 | O34: 6500
C35: (-) Bruno Parreira | D35: 4000 | E35: 4000 | F35: 4000 | G35: 4500 | H35: 4500 | I35: 4500 | J35: 5000 | K35: 5000 | L35: 5000 | M35: 5000 | N35: 5000 | O35: 5000
C36: (-) Jônatas Cavalcante | D36: 4000 | E36: 4000 | F36: 4000 | G36: 4500 | H36: 4500 | I36: 4500 | J36: 5000 | K36: 5000 | L36: 5000 | M36: 5000 | N36: 5000 | O36: 5000
... C41: (-) Bruno Silva | D41: 3000 | E41: 3000 | F41: 3000 | G41: 3000 | H41: 3000 | I41: 3000 | J41: 3000 | K41: 5500 | L41: 5500 | M41: 6000 | N41: 6000 | O41: 6000
C42: Novo - Contratar | E42: 5000 | F42: 5000 | G42: 5000 | H42: 5000 | I42: 5500 | J42: 5500 | K42: 5500 | L42: 5500 | M42: 6000 | N42: 6000 | O42: 6000
C43: Novo - Contratar | E43: 5000 | F43: 5000 | G43: 5000 | H43: 5000 | I43: 5000 | J43: 5000 | K43: 5500 | L43: 5500 | M43: 5500 | N43: 5500 | O43: 5500
C44: Novo - Contratar | F44: 5000 | G44: 5000 | H44: 5000 | I44: 5000 | J44: 5000 | K44: 5000 | L44: 5500 | M44: 5500 | N44: 5500 | O44: 5500
C45: Novo - Contratar | H45: 5000 | I45: 5000 | J45: 5000 | K45: 5000 | L45: 5000 | M45: 5500 | N45: 5500 | O45: 5500
C46: Novo - Contratar | J46: 5000 | K46: 5000 | L46: 5000 | M46: 5000 | N46: 5500 | O46: 5500
C47: Novo - Contratar | L47: 5000 | M47: 5000 | N47: 5000 | O47: 5000
...

Sheet Overview Old
B2: Trimestre | C2: 1 Trimestre | F2: 2 Trimestre | I2: 3 Trimestre | L2: 4 Trimestre | R2: 1 Trimestre
C3: Janeiro | D3: Feveiro | E3: Março | F3: Abril | G3: Maio | H3: Junho | I3: Julho | J3: Agosto | K3: Setembro | L3: Outubro | M3: Novembro | N3: Dezembro | O3: Total | R3: Inadimpência | S3: 0.06
B4: (+) MRR Ativo | C4: =Revenue!D5 -> 1156850 | D4: =Revenue!E5 -> 1267733.5 | E4: =Revenue!F5 -> 1368637.5 | F4: =Revenue!G5 -> 1485460.1 | G4: =Revenue!H5 -> 1591768.7 | H4: =Revenue!I5 -> 1688509.5 | I4: =Revenue!J5 -> 1806543.7 | J4: =Revenue!K5 -> 1913954.7 | ... N4: =Revenue!O5 -> 2337387.9 | O4: =sum(C4:N4) -> 20998078
B5: (+) Receita Pontual | C5: =Revenue!D37 -> 240000 | D5: =Revenue!E37 -> 280000 | E5: =Revenue!F37 -> 270000 | F5: =Revenue!G37 -> 288333.33 | G5: =Revenue!H37 -> 306666.67 | H5: =Revenue!I37 -> 325000 | I5: =Revenue!J37 -> 343333.33 | J5: =Revenue!K37 -> 361666.67 | ... N5: =Revenue!O37 -> 435000 | O5: =sum(C5:N5) -> 4045000 | R5: 2 Trimestre
B6: (+) Outras Receitas | C6: ='Outras Receitas'!C15 -> 20766.667 | D6: ='Outras Receitas'!D15 -> 60408 | E6: ='Outras Receitas'!E15 -> 25626.667 | F6: ='Outras Receitas'!F15 -> 43076.667 | G6: ='Outras Receitas'!G15 -> 90096.667 | H6: ='Outras Receitas'!H15 -> 48783.333 | I6: ='Outras Receitas'!I15 -> 85573.333 | J6: ='Outras Receitas'!J15 -> 135713.33 | ... N6: ='Outras Receitas'!N15 -> 137006.67 | O6: =sum(C6:N6) -> 1040111.3 | R6: Inadimpência | S6: 0.06
B7: (=) Receita Total Faturavel | C7: =C4+C5+C6 -> 1417616.7 | D7: =D4+D5+D6 -> 1608141.5 | E7: =E4+E5+E6 -> 1664264.2 | F7: =F4+F5+F6 -> 1816870.1 | G7: =G4+G5+G6 -> 1988532 | H7: =H4+H5+H6 -> 2062292.9 | I7: =I4+I5+I6 -> 2235450.3 | J7: =J4+J5+J6 -> 2411334.7 | ... O7: =O4+O5+O6 -> 26083189
B8: (-) Inadimplência | C8: =C7*$S$3 -> 85057 | D8: =D7*$S$3 -> 96488.49 | E8: =E7*$S$3 -> 99855.849 | F8: =F7*$S$6 -> 109012.21 | G8: =G7*$S$6 -> 119311.92 | H8: =H7*$S$6 -> 123737.57 | I8: =I7*$S$9 -> 134127.02 | J8: =J7*$S$9 -> 144680.08 | K8: =K7*$S$9 -> 148244.73 | L8: =L7*$S$12 -> 159959.15 | M8: =M7*$S$12 -> 169953.67 | N8: =N7*$S$12 -> 174563.67 | O8: =sum(C8:N8) -> 1564991.4 | P8: =O8/$O$7 -> 0.06 | R8: 3 Trimestre
B9: (-) Impostos Sob Receita | C9: ='Tributário'!F11+'Tributário'!F12+'Tributário'!F13 -> 133132.3 | D9: ='Tributário'!G11+'Tributário'!G12+'Tributário'!G13 -> 150146.17 | E9: ='Tributário'!H11+'Tributário'!H12+'Tributário'!H13 -> 155157.92 | F9: ='Tributário'!I11+'Tributário'!I12+'Tributário'!I13 -> 170420.41 | G9: ='Tributário'!J11+'Tributário'!J12+'Tributário'!J13 -> 185749.82 | H9: ='Tributário'!K11+'Tributário'!K12+'Tributário'!K13 -> 192336.66 | I9: ='Tributário'!L11+'Tributário'!L12+'Tributário'!L13 -> 207799.63 | J9: ='Tributário'!M11+'Tributário'!M12+'Tributário'!M13 -> 223506.1 | ... N9: ='Tributário'!Q11+'Tributário'!Q12+'Tributário'!Q13 -> 267982.85 | O9: =sum(C9:N9) -> 2422411.4 | P9: =O9/$O$7 -> 0.092872516 | R9: Inadimpência | S9: 0.06
B10: (=) Receita Líquida | C10: =C7-C8-C9 -> 1199427.4 | D10: =D7-D8-D9 -> 1361506.8 | E10: =E7-E8-E9 -> 1409250.4 | F10: =F7-F8-F9 -> 1537437.5 | G10: =G7-G8-G9 -> 1683470.3 | H10: =H7-H8-H9 -> 1746218.6 | I10: =I7-I8-I9 -> 1893523.7 | J10: =J7-J8-J9 -> 2043148.5 | ... N10: =N7-N8-N9 -> 2466848 | O10: =sum(C10:N10) -> 22095787 | Q10: =O10/$O$7 -> 0.84712748
B11: (-) CSV | C11: =CSV!D4 -> 345754.4 | D11: =CSV!E4 -> 380706.3 | E11: =CSV!F4 -> 399437.54 | F11: =CSV!G4 -> 465597.96 | G11: =CSV!H4 -> 488400.64 | H11: =CSV!I4 -> 495996.08 | I11: =CSV!J4 -> 557632.94 | J11: =CSV!K4 -> 583914.17 | ... N11: =CSV!O4 -> 687435.48 | O11: =sum(C11:N11) -> 6314099.1 | P11: =O11/$O$7 -> 0.24207542 | R11: 4 Trimestre
B12: (=) Margem Bruta | C12: =C10-C11 -> 853672.97 | D12: =D10-D11 -> 980800.54 | E12: =E10-E11 -> 1009812.8 | F12: =F10-F11 -> 1071839.5 | G12: =G10-G11 -> 1195069.6 | H12: =H10-H11 -> 1250222.5 | I12: =I10-I11 -> 1335890.7 | J12: =J10-J11 -> 1459234.4 | ... N12: =N10-N11 -> 1779412.6 | O12: =sum(C12:N12) -> 15781688 | Q12: =O12/$O$7 -> 0.60505206 | R12: Inadimpência | S12: 0.06
B13: (-) CAC | C13: =CAC!C6 -> 262495.71 | D13: =CAC!D6 -> 285895.71 | E13: =CAC!E6 -> 311895.71 | F13: =CAC!F6 -> 337573.77 | G13: =CAC!G6 -> 422573.77 | H13: =CAC!H6 -> 362573.77 | I13: =CAC!I6 -> 453925.18 | J13: =CAC!J6 -> 371925.18 | ... N13: =CAC!N6 -> 428776.58 | O13: =sum(C13:N13) -> 4449113.7 | P13: =O13/$O$7 -> 0.17057399
B14: (-) SG&A | C14: ='SG&A'!C6 -> 298446 | D14: ='SG&A'!D6 -> 292038 | E14: ='SG&A'!E6 -> 294283 | F14: ='SG&A'!F6 -> 292041 | G14: ='SG&A'!G6 -> 294837 | H14: ='SG&A'!H6 -> 299735 | I14: ='SG&A'!I6 -> 317499 | J14: ='SG&A'!J6 -> 304744 | ... N14: ='SG&A'!N6 -> 363847 | O14: =sum(C14:N14) -> 3735216 | P14: =O14/$O$7 -> 0.14320396
B15: (=) EBITDA | C15: =C12-C13-C14 -> 292731.26 | D15: =D12-D13-D14 -> 402866.83 | E15: =E12-E13-E14 -> 403634.14 | F15: =F12-F13-F14 -> 442224.76 | G15: =G12-G13-G14 -> 477658.87 | H15: =H12-H13-H14 -> 587913.76 | I15: =I12-I13-I14 -> 564466.57 | J15: =J12-J13-J14 -> 782565.2 | ... N15: =N12-N13-N14 -> 986788.97 | O15: =sum(C15:N15) -> 7597357.9 | Q15: =O15/$O$7 -> 0.29127411
B16: (-) IR + CSLL | C16: ='Tributário'!F14 -> 99528.628 | D16: ='Tributário'!G14 -> 136974.72 | E16: ='Tributário'!H14 -> 137235.61 | F16: ='Tributário'!I14 -> 150356.42 | G16: ='Tributário'!J14 -> 162404.02 | H16: ='Tributário'!K14 -> 199890.68 | I16: ='Tributário'!L14 -> 191918.63 | J16: ='Tributário'!M14 -> 266072.17 | ... N16: ='Tributário'!Q14 -> 335508.25 | O16: =sum(C16:N16) -> 2583101.7 | P16: =O16/$O$7 -> 0.099033199
B17: (-) CAPEX | C17: ='CAPEX e Giro'!D5 -> 35000 | D17: ='CAPEX e Giro'!E5 -> 35000 | E17: ='CAPEX e Giro'!F5 -> 35000 | F17: ='CAPEX e Giro'!G5 -> 35000 | G17: ='CAPEX e Giro'!H5 -> 35000 | H17: ='CAPEX e Giro'!I5 -> 35000 | I17: ='CAPEX e Giro'!J5 -> 35000 | J17: ='CAPEX e Giro'!K5 -> 35000 | ... N17: ='CAPEX e Giro'!O5 -> 35000 | O17: =sum(C17:N17) -> 420000 | P17: =O17/$O$7 -> 0.016102325
B18: (=) Geração de Caixa | C18: =C15-C16-C17 -> 158202.63 | D18: =D15-D16-D17 -> 230892.11 | E18: =E15-E16-E17 -> 231398.53 | F18: =F15-F16-F17 -> 256868.34 | G18: =G15-G16-G17 -> 280254.86 | H18: =H15-H16-H17 -> 353023.08 | I18: =I15-I16-I17 -> 337547.94 | J18: =J15-J16-J17 -> 481493.03 | ... O18: =O15-O16-O17 -> 4594256.2 | P18: =O18/$O$7 -> 0.17613859
B19: (%) Margem Geração | C19: =C18/C7 -> 0.11159761 | D19: =D18/D7 -> 0.14357698 | E19: =E18/E7 -> 0.13903955 | F19: =F18/F7 -> 0.14137958 | G19: =G18/G7 -> 0.14093555 | H19: =H18/H7 -> 0.1711799 | I19: =I18/I7 -> 0.15099773 | J19: =J18/J7 -> 0.19967905 | ... N19: =N18/N7 -> 0.21182439
B21: Métricas Gerais
B22: Receita Total | C22: =C7-C8 -> 1332559.7 | D22: =D7-D8 -> 1511653 | E22: =E7-E8 -> 1564408.3 | F22: =F7-F8 -> 1707857.9 | G22: =G7-G8 -> 1869220.1 | H22: =H7-H8 -> 1938555.3 | I22: =I7-I8 -> 2101323.3 | J22: =J7-J8 -> 2266654.6 | ... N22: =N7-N8 -> 2734830.9
B23: Despesa Total | C23: =C9+C11+C13+C14+C16+C17 -> 1174357 | D23: =D9+D11+D13+D14+D16+D17 -> 1280760.9 | E23: =E9+E11+E13+E14+E16+E17 -> 1333009.8 | F23: =F9+F11+F13+F14+F16+F17 -> 1450989.6 | G23: =G9+G11+G13+G14+G16+G17 -> 1588965.3 | H23: =H9+H11+H13+H14+H16+H17 -> 1585532.2 | I23: =I9+I11+I13+I14+I16+I17 -> 1763775.4 | J23: =J9+J11+J13+J14+J16+J17 -> 1785161.6 | ... N23: =N9+N11+N13+N14+N16+N17 -> 2118550.2
B24: Vendas MRR | C24: =CAC!Q7 -> 215000 | D24: =CAC!R7 -> 215000 | E24: =CAC!S7 -> 215000 | F24: =CAC!T7 -> 240000 | G24: =CAC!U7 -> 240000 | H24: =CAC!V7 -> 240000 | I24: =CAC!W7 -> 270000 | J24: =CAC!X7 -> 270000 | ... N24: =CAC!AB7 -> 300000
B25: Vendas Pontual | C25: =CAC!Q38 -> 270000 | D25: =CAC!R38 -> 270000 | E25: =CAC!S38 -> 270000 | F25: =CAC!T38 -> 325000 | G25: =CAC!U38 -> 325000 | H25: =CAC!V38 -> 325000 | I25: =CAC!W38 -> 380000 | J25: =CAC!X38 -> 380000 | ... N25: =CAC!AB38 -> 435000
B26: Numero de Colaboradores | C26: =CSV!D7+count('SG&A'!C20:C22)+count('SG&A'!C28:C37)+count(CAC!C21:C38)+count(CAC!C44:C59)+count(CAC!C66:C71)+count(CAC!C77:C86) -> 110 | D26: =CSV!E7+count('SG&A'!D20:D22)+count('SG&A'!D28:D37)+count(CAC!D21:D38)+count(CAC!D44:D59)+count(CAC!D66:D71)+count(CAC!D77:D86) -> 118 | E26: =CSV!F7+count('SG&A'!E20:E22)+count('SG&A'!E28:E37)+count(CAC!E21:E38)+count(CAC!E44:E59)+count(CAC!E66:E71)+count(CAC!E77:E86) -> 123 | F26: =CSV!G7+count('SG&A'!F20:F22)+count('SG&A'!F28:F37)+count(CAC!F21:F38)+count(CAC!F44:F59)+count(CAC!F66:F71)+count(CAC!F77:F86) -> 135 | G26: =CSV!H7+count('SG&A'!G20:G22)+count('SG&A'!G28:G37)+count(CAC!G21:G38)+count(CAC!G44:G59)+count(CAC!G66:G71)+count(CAC!G77:G86) -> 139 | H26: =CSV!I7+count('SG&A'!H20:H22)+count('SG&A'!H28:H37)+count(CAC!H21:H38)+count(CAC!H44:H59)+count(CAC!H66:H71)+count(CAC!H77:H86) -> 141 | I26: =CSV!J7+count('SG&A'!I20:I22)+count('SG&A'!I28:I37)+count(CAC!I21:I38)+count(CAC!I44:I59)+count(CAC!I66:I71)+count(CAC!I77:I86) -> 147 | J26: =CSV!K7+count('SG&A'!J20:J22)+count('SG&A'!J28:J37)+count(CAC!J21:J38)+count(CAC!J44:J59)+count(CAC!J66:J71)+count(CAC!J77:J86) -> 152 | ... N26: =CSV!O7+count('SG&A'!N20:N22)+count('SG&A'!N28:N37)+count(CAC!N21:N38)+count(CAC!N44:N59)+count(CAC!N66:N71)+count(CAC!N77:N86) -> 169
B27: Receita Cabeça | C27: =C7/C26 -> 12887.424 | D27: =D7/D26 -> 13628.318 | E27: =E7/E26 -> 13530.603 | F27: =F7/F26 -> 13458.297 | G27: =G7/G26 -> 14305.986 | H27: =H7/H26 -> 14626.19 | I27: =I7/I26 -> 15207.145 | J27: =J7/J26 -> 15864.044 | ... N27: =N7/N26 -> 17215.352
B28: MRR Cabeça | C28: =C4/C26 -> 10516.818 | D28: =D4/D26 -> 10743.504 | E28: =E4/E26 -> 11127.134 | F28: =F4/F26 -> 11003.408 | G28: =G4/G26 -> 11451.573 | H28: =H4/H26 -> 11975.245 | I28: =I4/I26 -> 12289.413 | J28: =J4/J26 -> 12591.807 | ... N28: =N4/N26 -> 13830.698
B29: Numero de Clientes | C29: =C30/1.38 -> 300.66977 | D29: =D30/1.38 -> 330.2517 | E29: =E30/1.38 -> 352.00541 | F29: =F30/1.38 -> 377.78291 | G29: =G30/1.38 -> 402.43492 | H29: =H30/1.38 -> 423.7875 | I29: =I30/1.38 -> 449.22341 | J29: =J30/1.38 -> 474.6896 | K29: =K30/1.37 -> 500.42409 | L29: =L30/1.4 -> 515.46212 | M29: =M30/1.4 -> 541.19276 | N29: =N30/1.4 -> 563.56566
B30: Numero de Contratos | C30: =CSV!C12+CSV!C85+CSV!C141+CSV!C202+CSV!C225+CAC!Q42+CAC!Q47+CAC!Q52+CAC!Q57+CAC!Q62+CAC!Q67 -> 414.92429 | D30: =CSV!D12+CSV!D85+CSV!D141+CSV!D202+CSV!D225+CAC!R42+CAC!R47+CAC!R52+CAC!R57+CAC!R62+CAC!R67 -> 455.74735 | E30: =CSV!E12+CSV!E85+CSV!E141+CSV!E202+CSV!E225+CAC!S42+CAC!S47+CAC!S52+CAC!S57+CAC!S62+CAC!S67 -> 485.76747 | F30: =CSV!F12+CSV!F85+CSV!F141+CSV!F202+CSV!F225+CAC!T42+CAC!T47+CAC!T52+CAC!T57+CAC!T62+CAC!T67 -> 521.34042 | G30: =CSV!G12+CSV!G85+CSV!G141+CSV!G202+CSV!G225+CAC!U42+CAC!U47+CAC!U52+CAC!U57+CAC!U62+CAC!U67 -> 555.36019 | H30: =CSV!H12+CSV!H85+CSV!H141+CSV!H202+CSV!H225+CAC!V42+CAC!V47+CAC!V52+CAC!V57+CAC!V62+CAC!V67 -> 584.82675 | I30: =CSV!I12+CSV!I85+CSV!I141+CSV!I202+CSV!I225+CAC!W42+CAC!W47+CAC!W52+CAC!W57+CAC!W62+CAC!W67 -> 619.9283 | J30: =CSV!J12+CSV!J85+CSV!J141+CSV!J202+CSV!J225+CAC!X42+CAC!X47+CAC!X52+CAC!X57+CAC!X62+CAC!X67 -> 655.07165 | ... N30: =CSV!N12+CSV!N85+CSV!N141+CSV!N202+CSV!N225+CAC!AB42+CAC!AB47+CAC!AB52+CAC!AB57+CAC!AB62+CAC!AB67 -> 788.99192
B31: Ticket Medio Cliente | C31: =C7/C29 -> 4714.8626 | D31: =D7/D29 -> 4869.442 | E31: =E7/E29 -> 4727.9504 | F31: =F7/F29 -> 4809.2967 | G31: =G7/G29 -> 4941.2512 | H31: =H7/H29 -> 4866.3372 | I31: =I7/I29 -> 4976.2552 | J31: =J7/J29 -> 5079.8137 | ... N31: =N7/N29 -> 5162.4766
B32: Ticket Medio Contratos | C32: =C7/C30 -> 3416.5671 | D32: =D7/D30 -> 3528.5811 | E32: =E7/E30 -> 3426.051 | F32: =F7/F30 -> 3484.9976 | G32: =G7/G30 -> 3580.6168 | H32: =H7/H30 -> 3526.3313 | I32: =I7/I30 -> 3605.9821 | J32: =J7/J30 -> 3681.0244 | ... N32: =N7/N30 -> 3687.4833
B33: Churn Mês | C33: =Revenue!D32 -> 104116.5 | D33: =Revenue!E32 -> 114096.01 | E33: =Revenue!F32 -> 123177.37 | F33: =Revenue!G32 -> 133691.41 | G33: =Revenue!H32 -> 143259.18 | H33: =Revenue!I32 -> 151965.86 | I33: =Revenue!J32 -> 162588.93 | J33: =Revenue!K32 -> 172255.93 | ... N33: =Revenue!O32 -> 210364.91
B34: Aliquota Imposto Efetiva | C34: =(C16+C9)/C7 -> 0.16412118 | D34: =(D16+D9)/D7 -> 0.17854206 | E34: =(E16+E9)/E7 -> 0.17568937 | F34: =(F16+F9)/F7 -> 0.17655463 | G34: =(G16+G9)/G7 -> 0.17508083 | H34: =(H16+H9)/H7 -> 0.19018993 | I34: =(I16+I9)/I7 -> 0.17880883 | J34: =(J16+J9)/J7 -> 0.20303207 | ... O34: =(O16+O9)/O7 -> 0.19190571
B35: Geracao de caixa | C35: =C18 -> 158202.63 | D35: =D18 -> 230892.11 | E35: =E18 -> 231398.53 | F35: =F18 -> 256868.34 | G35: =G18 -> 280254.86 | H35: =H18 -> 353023.08 | I35: =I18 -> 337547.94 | J35: =J18 -> 481493.03 | ... N35: =N18 -> 616280.72
B36: Margem de geração | C36: =C19 -> 0.11159761 | D36: =D19 -> 0.14357698 | E36: =E19 -> 0.13903955 | F36: =F19 -> 0.14137958 | G36: =G19 -> 0.14093555 | H36: =H19 -> 0.1711799 | I36: =I19 -> 0.15099773 | J36: =J19 -> 0.19967905 | ... N36: =N19 -> 0.21182439 | O36: =P18 -> 0.17613859
B37: Saldo de Caixa | C37: =535000+C35 -> 693202.63 | D37: =C37+D35 -> 924094.74 | E37: =D37+E35 -> 1155493.3 | F37: =E37+F35 -> 1412361.6 | G37: =F37+G35 -> 1692616.5 | H37: =G37+H35 -> 2045639.5 | I37: =H37+I35 -> 2383187.5 | J37: =I37+J35 -> 2864680.5 | K37: =J37+K35 -> 3360111.3 | ... N37: =M37+N35 -> 5129256.2
B39: Numero de Colaboradores | C39: =CSV!D7+count('SG&A'!C20:C22)+count('SG&A'!C28:C37)+count(CAC!C21:C38)+count(CAC!C44:C59)+count(CAC!C66:C71)+count(CAC!C77:C86) -> 110 | D39: =CSV!E7+count('SG&A'!D20:D22)+count('SG&A'!D28:D37)+count(CAC!D21:D38)+count(CAC!D44:D59)+count(CAC!D66:D71)+count(CAC!D77:D86) -> 118 | E39: =CSV!F7+count('SG&A'!E20:E22)+count('SG&A'!E28:E37)+count(CAC!E21:E38)+count(CAC!E44:E59)+count(CAC!E66:E71)+count(CAC!E77:E86) -> 123 | F39: =CSV!G7+count('SG&A'!F20:F22)+count('SG&A'!F28:F37)+count(CAC!F21:F38)+count(CAC!F44:F59)+count(CAC!F66:F71)+count(CAC!F77:F86) -> 135 | G39: =CSV!H7+count('SG&A'!G20:G22)+count('SG&A'!G28:G37)+count(CAC!G21:G38)+count(CAC!G44:G59)+count(CAC!G66:G71)+count(CAC!G77:G86) -> 139 | H39: =CSV!I7+count('SG&A'!H20:H22)+count('SG&A'!H28:H37)+count(CAC!H21:H38)+count(CAC!H44:H59)+count(CAC!H66:H71)+count(CAC!H77:H86) -> 141 | I39: =CSV!J7+count('SG&A'!I20:I22)+count('SG&A'!I28:I37)+count(CAC!I21:I38)+count(CAC!I44:I59)+count(CAC!I66:I71)+count(CAC!I77:I86) -> 147 | J39: =CSV!K7+count('SG&A'!J20:J22)+count('SG&A'!J28:J37)+count(CAC!J21:J38)+count(CAC!J44:J59)+count(CAC!J66:J71)+count(CAC!J77:J86) -> 152 | ... N39: =CSV!O7+count('SG&A'!N20:N22)+count('SG&A'!N28:N37)+count(CAC!N21:N38)+count(CAC!N44:N59)+count(CAC!N66:N71)+count(CAC!N77:N86) -> 169
B40: Pessoas em CSV | C40: =CSV!D7 -> 73 | D40: =CSV!E7 -> 80 | E40: =CSV!F7 -> 83 | F40: =CSV!G7 -> 93 | G40: =CSV!H7 -> 97 | H40: =CSV!I7 -> 98 | I40: =CSV!J7 -> 104 | J40: =CSV!K7 -> 108 | ... N40: =CSV!O7 -> 122
B41: Pessoas em CAC | C41: =CAC!C5 -> 24 | D41: =CAC!D5 -> 25 | E41: =CAC!E5 -> 27 | F41: =CAC!F5 -> 30 | G41: =CAC!G5 -> 30 | H41: =CAC!H5 -> 30 | I41: =CAC!I5 -> 30 | J41: =CAC!J5 -> 31 | ... N41: =CAC!N5 -> 34
B42: Pessoas em SGEA | C42: ='SG&A'!C5 -> 12 | D42: ='SG&A'!D5 -> 12 | E42: ='SG&A'!E5 -> 12 | F42: ='SG&A'!F5 -> 11 | G42: ='SG&A'!G5 -> 11 | H42: ='SG&A'!H5 -> 12 | I42: ='SG&A'!I5 -> 12 | J42: ='SG&A'!J5 -> 12 | ... N42: ='SG&A'!N5 -> 12
B45: Despesa Total | C45: =C23 -> 1174357 | D45: =D23 -> 1280760.9 | E45: =E23 -> 1333009.8 | F45: =F23 -> 1450989.6 | G45: =G23 -> 1588965.3 | H45: =H23 -> 1585532.2 | I45: =I23 -> 1763775.4 | J45: =J23 -> 1785161.6 | ... N45: =N23 -> 2118550.2
...

Sheet BP ORÇADO X REALIZADO
B2: Trimestre | C2: 1 Trimestre | I2: 2 Trimestre | O2: 3 Trimestre | U2: 4 Trimestre | AD2: 1 Trimestre
C3: Janeiro | D3: Realizado Jan | E3: Feveiro | F3: Realizado Fev | G3: Março | H3: Realizado Mar | I3: Abril | J3: Realizado Abr | K3: Maio | L3: Realizado Mai | M3: Junho | N3: Realizado Jun | O3: Julho | P3: Realizado Jul | Q3: Agosto | R3: Realizado Ago | S3: Setembro | T3: Realizado Set | U3: Outubro | V3: Realizado Out | W3: Novembro | X3: Realizado Nov | Y3: Dezembro | Z3: Realizado Dez | AA3: Total | AD3: Inadimpência | AE3: 0.06
B4: (+) MRR Ativo | C4: =Revenue!D5 -> 1156850 | D4: 1119046 | E4: =Revenue!E5 -> 1267733.5 | G4: =Revenue!F5 -> 1368637.5 | I4: =Revenue!G5 -> 1485460.1 | K4: =Revenue!H5 -> 1591768.7 | M4: =Revenue!I5 -> 1688509.5 | O4: =Revenue!J5 -> 1806543.7 | Q4: =Revenue!K5 -> 1913954.7 | S4: =Revenue!L5 -> 2011698.8 | U4: =Revenue!M5 -> 2130645.9 | W4: =Revenue!N5 -> 2238887.8 | Y4: =Revenue!O5 -> 2337387.9 | AA4: =C4+E4+G4+I4+K4+M4+O4+Q4+S4+U4+W4+Y4 -> 20998078
B5: (+) Receita Pontual | C5: =Revenue!D37 -> 240000 | D5: =D7-D4 -> 326472 | E5: =Revenue!E37 -> 280000 | G5: =Revenue!F37 -> 270000 | I5: =Revenue!G37 -> 288333.33 | K5: =Revenue!H37 -> 306666.67 | M5: =Revenue!I37 -> 325000 | O5: =Revenue!J37 -> 343333.33 | Q5: =Revenue!K37 -> 361666.67 | S5: =Revenue!L37 -> 380000 | U5: =Revenue!M37 -> 398333.33 | W5: =Revenue!N37 -> 416666.67 | Y5: =Revenue!O37 -> 435000 | AA5: =C5+E5+G5+I5+K5+M5+O5+Q5+S5+U5+W5+Y5 -> 4045000 | AD5: 2 Trimestre
B6: (+) Outras Receitas | C6: ='Outras Receitas'!C15 -> 20766.667 | E6: ='Outras Receitas'!D15 -> 60408 | G6: ='Outras Receitas'!E15 -> 25626.667 | I6: ='Outras Receitas'!F15 -> 43076.667 | K6: ='Outras Receitas'!G15 -> 90096.667 | M6: ='Outras Receitas'!H15 -> 48783.333 | O6: ='Outras Receitas'!I15 -> 85573.333 | Q6: ='Outras Receitas'!J15 -> 135713.33 | S6: ='Outras Receitas'!K15 -> 79046.667 | U6: ='Outras Receitas'!L15 -> 137006.67 | W6: ='Outras Receitas'!M15 -> 177006.67 | Y6: ='Outras Receitas'!N15 -> 137006.67 | AA6: =C6+E6+G6+I6+K6+M6+O6+Q6+S6+U6+W6+Y6 -> 1040111.3 | AD6: Inadimpência | AE6: 0.06
B7: (=) Receita Total Faturavel | C7: =C4+C5+C6 -> 1417616.7 | D7: 1445518 | E7: =E4+E5+E6 -> 1608141.5 | G7: =G4+G5+G6 -> 1664264.2 | I7: =I4+I5+I6 -> 1816870.1 | K7: =K4+K5+K6 -> 1988532 | M7: =M4+M5+M6 -> 2062292.9 | O7: =O4+O5+O6 -> 2235450.3 | Q7: =Q4+Q5+Q6 -> 2411334.7 | S7: =S4+S5+S6 -> 2470745.5 | U7: =U4+U5+U6 -> 2665985.9 | W7: =W4+W5+W6 -> 2832561.1 | Y7: =Y4+Y5+Y6 -> 2909394.5 | AA7: =AA4+AA5+AA6 -> 26083189
B8: (-) Inadimplência | C8: =C7*$AE$3 -> 85057 | D8: 283761 | E8: =E7*$AE$3 -> 96488.49 | G8: =G7*$AE$3 -> 99855.849 | I8: =I7*$AE$6 -> 109012.21 | K8: =K7*$AE$6 -> 119311.92 | M8: =M7*$AE$6 -> 123737.57 | O8: =O7*$AE$9 -> 134127.02 | Q8: =Q7*$AE$9 -> 144680.08 | S8: =S7*$AE$9 -> 148244.73 | U8: =U7*$AE$12 -> 159959.15 | W8: =W7*$AE$12 -> 169953.67 | Y8: =Y7*$AE$12 -> 174563.67 | AA8: =C8+E8+G8+I8+K8+M8+O8+Q8+S8+U8+W8+Y8 -> 1564991.4 | AB8: =AA8/$AA$7 -> 0.06 | AD8: 3 Trimestre
B9: (-) Impostos Sob Receita | C9: ='Tributário'!F11+'Tributário'!F12+'Tributário'!F13 -> 133132.3 | D9: 104303 | E9: ='Tributário'!G11+'Tributário'!G12+'Tributário'!G13 -> 150146.17 | G9: ='Tributário'!H11+'Tributário'!H12+'Tributário'!H13 -> 155157.92 | I9: ='Tributário'!I11+'Tributário'!I12+'Tributário'!I13 -> 170420.41 | K9: ='Tributário'!J11+'Tributário'!J12+'Tributário'!J13 -> 185749.82 | M9: ='Tributário'!K11+'Tributário'!K12+'Tributário'!K13 -> 192336.66 | O9: ='Tributário'!L11+'Tributário'!L12+'Tributário'!L13 -> 207799.63 | Q9: ='Tributário'!M11+'Tributário'!M12+'Tributário'!M13 -> 223506.1 | S9: ='Tributário'!N11+'Tributário'!N12+'Tributário'!N13 -> 228811.48 | U9: ='Tributário'!O11+'Tributário'!O12+'Tributário'!O13 -> 246246.46 | W9: ='Tributário'!P11+'Tributário'!P12+'Tributário'!P13 -> 261121.62 | Y9: ='Tributário'!Q11+'Tributário'!Q12+'Tributário'!Q13 -> 267982.85 | AA9: =C9+E9+G9+I9+K9+M9+O9+Q9+S9+U9+W9+Y9 -> 2422411.4 | AB9: =AA9/$AA$7 -> 0.092872516 | AD9: Inadimpência | AE9: 0.06
B10: (=) Receita Líquida | C10: =C7-C8-C9 -> 1199427.4 | D10: =D7-D8-D9 -> 1057454 | E10: =E7-E8-E9 -> 1361506.8 | G10: =G7-G8-G9 -> 1409250.4 | I10: =I7-I8-I9 -> 1537437.5 | K10: =K7-K8-K9 -> 1683470.3 | M10: =M7-M8-M9 -> 1746218.6 | O10: =O7-O8-O9 -> 1893523.7 | Q10: =Q7-Q8-Q9 -> 2043148.5 | S10: =S7-S8-S9 -> 2093689.3 | U10: =U7-U8-U9 -> 2259780.3 | W10: =W7-W8-W9 -> 2401485.8 | Y10: =Y7-Y8-Y9 -> 2466848 | AA10: =C10+E10+G10+I10+K10+M10+O10+Q10+S10+U10+W10+Y10 -> 22095787 | AC10: =AA10/$AA$7 -> 0.84712748
B11: (-) CSV - Salários | C11: =CSV!D4 -> 345754.4 | D11: 349675 | E11: =CSV!E4 -> 380706.3 | G11: =CSV!F4 -> 399437.54 | I11: =CSV!G4 -> 465597.96 | K11: =CSV!H4 -> 488400.64 | M11: =CSV!I4 -> 495996.08 | O11: =CSV!J4 -> 557632.94 | Q11: =CSV!K4 -> 583914.17 | S11: =CSV!L4 -> 598990.1 | U11: =CSV!M4 -> 647359.19 | W11: =CSV!N4 -> 662874.26 | Y11: =CSV!O4 -> 687435.48 | AA11: =C11+E11+G11+I11+K11+M11+O11+Q11+S11+U11+W11+Y11 -> 6314099.1 | AB11: =AA11/$AA$7 -> 0.24207542 | AD11: 4 Trimestre
B12: (-) CSV - Benefício | C12: =(CSV!D7*400) -> 29200 | D12: 37241 | E12: =(CSV!E7*400) -> 32000 | G12: =(CSV!F7*400) -> 33200 | I12: =(CSV!G7*400) -> 37200 | K12: =(CSV!H7*400) -> 38800 | M12: =(CSV!I7*400) -> 39200 | O12: =(CSV!J7*400) -> 41600 | Q12: =(CSV!K7*400) -> 43200 | S12: =(CSV!L7*400) -> 44000 | U12: =(CSV!M7*400) -> 46400 | W12: =(CSV!N7*400) -> 47600 | Y12: =(CSV!O7*400) -> 48800 | AA12: =C12+E12+G12+I12+K12+M12+O12+Q12+S12+U12+W12+Y12 -> 481200 | AB12: =AA12/$AA$7 -> 0.018448664 | AD12: Inadimpência | AE12: 0.06
B13: (-) CSV - Stack Tecnologia | C13: ='SG&A'!C42 -> 41540 | E13: ='SG&A'!D42 -> 41932 | G13: ='SG&A'!E42 -> 42177 | I13: ='SG&A'!F42 -> 44635 | K13: ='SG&A'!G42 -> 44831 | M13: ='SG&A'!H42 -> 44929 | O13: ='SG&A'!I42 -> 62293 | Q13: ='SG&A'!J42 -> 47538 | S13: ='SG&A'!K42 -> 47685 | U13: ='SG&A'!L42 -> 49098 | W13: ='SG&A'!M42 -> 49245 | Y13: ='SG&A'!N42 -> 49441 | AA13: =C13+E13+G13+I13+K13+M13+O13+Q13+S13+U13+W13+Y13 -> 565344 | AB13: =AA13/$AA$7 -> 0.02167465
B14: (=) Margem Bruta | C14: =C10-C11-C12-C13 -> 782932.97 | D14: =D10-D11-D12 -> 670538 | E14: =E10-E11-E12-E13 -> 906868.54 | G14: =G10-G11-G12-G13 -> 934435.85 | I14: =I10-I11-I12-I13 -> 990004.53 | K14: =K10-K11-K12-K13 -> 1111438.6 | M14: =M10-M11-M12-M13 -> 1166093.5 | O14: =O10-O11-O12-O13 -> 1231997.7 | Q14: =Q10-Q11-Q12-Q13 -> 1368496.4 | S14: =S10-S11-S12-S13 -> 1403014.2 | U14: =U10-U11-U12-U13 -> 1516923.1 | W14: =W10-W11-W12-W13 -> 1641766.6 | Y14: =Y10-Y11-Y12-Y13 -> 1681171.6 | AA14: =C14+E14+G14+I14+K14+M14+O14+Q14+S14+U14+W14+Y14 -> 14735144 | AC14: =AA14/$AA$7 -> 0.56492875
B15: (-) CAC | C15: =CAC!C6 -> 262495.71 | D15: 236184 | E15: =CAC!D6 -> 285895.71 | G15: =CAC!E6 -> 311895.71 | I15: =CAC!F6 -> 337573.77 | K15: =CAC!G6 -> 422573.77 | M15: =CAC!H6 -> 362573.77 | O15: =CAC!I6 -> 453925.18 | Q15: =CAC!J6 -> 371925.18 | S15: =CAC!K6 -> 384925.18 | U15: =CAC!L6 -> 420776.58 | W15: =CAC!M6 -> 405776.58 | Y15: =CAC!N6 -> 428776.58 | AA15: =C15+E15+G15+I15+K15+M15+O15+Q15+S15+U15+W15+Y15 -> 4449113.7 | AB15: =AA15/$AA$7 -> 0.17057399
B16: (-) SG&A | C16: ='SG&A'!C6-C12-C13 -> 227706 | D16: 286179 | E16: ='SG&A'!D6-E12-E13 -> 218106 | G16: ='SG&A'!E6-G12-G13 -> 218906 | I16: ='SG&A'!F6-I12-I13 -> 210206 | K16: ='SG&A'!G6-K12-K13 -> 211206 | M16: ='SG&A'!H6-M12-M13 -> 215606 | O16: ='SG&A'!I6-O12-O13 -> 213606 | Q16: ='SG&A'!J6-Q12-Q13 -> 214006 | S16: ='SG&A'!K6-S12-S13 -> 214406 | U16: ='SG&A'!L6-U12-U13 -> 234506 | W16: ='SG&A'!M6-W12-W13 -> 244806 | Y16: ='SG&A'!N6-Y12-Y13 -> 265606 | AA16: =C16+E16+G16+I16+K16+M16+O16+Q16+S16+U16+W16+Y16 -> 2688672 | AB16: =AA16/$AA$7 -> 0.10308065
B17: (-) Bônus | C17: =Overview!C17 -> 54000 | E17: =Overview!D17 -> 23000 | G17: =Overview!E17 -> 23000
B18: (=) EBITDA | C18: =C14-C15-C16-C17 -> 238731.26 | D18: =D14-D15-D16 -> 148175 | E18: =E14-E15-E16-E17 -> 379866.83 | G18: =G14-G15-G16-G17 -> 380634.14 | I18: =I14-I15-I16-I17 -> 442224.76 | K18: =K14-K15-K16-K17 -> 477658.87 | M18: =M14-M15-M16-M17 -> 587913.76 | O18: =O14-O15-O16-O17 -> 564466.57 | Q18: =Q14-Q15-Q16 -> 782565.2 | S18: =S14-S15-S16 -> 803682.99 | U18: =U14-U15-U16 -> 861640.54 | W18: =W14-W15-W16 -> 991183.99 | Y18: =Y14-Y15-Y16 -> 986788.97 | AA18: =C18+E18+G18+I18+K18+M18+O18+Q18+S18+U18+W18+Y18 -> 7497357.9 | AC18: =AA18/$AA$7 -> 0.28744023
B19: (-) IR + CSLL | C19: ='Tributário'!F14 -> 99528.628 | E19: ='Tributário'!G14 -> 136974.72 | G19: ='Tributário'!H14 -> 137235.61 | I19: ='Tributário'!I14 -> 150356.42 | K19: ='Tributário'!J14 -> 162404.02 | M19: ='Tributário'!K14 -> 199890.68 | O19: ='Tributário'!L14 -> 191918.63 | Q19: ='Tributário'!M14 -> 266072.17 | S19: ='Tributário'!N14 -> 273252.22 | U19: ='Tributário'!O14 -> 292957.78 | W19: ='Tributário'!P14 -> 337002.56 | Y19: ='Tributário'!Q14 -> 335508.25 | AA19: =C19+E19+G19+I19+K19+M19+O19+Q19+S19+U19+W19+Y19 -> 2583101.7 | AB19: =AA19/$AA$7 -> 0.099033199
B20: (-) CAPEX | C20: ='CAPEX e Giro'!D5 -> 35000 | E20: ='CAPEX e Giro'!E5 -> 35000 | G20: ='CAPEX e Giro'!F5 -> 35000 | I20: ='CAPEX e Giro'!G5 -> 35000 | K20: ='CAPEX e Giro'!H5 -> 35000 | M20: ='CAPEX e Giro'!I5 -> 35000 | O20: ='CAPEX e Giro'!J5 -> 35000 | Q20: ='CAPEX e Giro'!K5 -> 35000 | S20: ='CAPEX e Giro'!L5 -> 35000 | U20: ='CAPEX e Giro'!M5 -> 35000 | W20: ='CAPEX e Giro'!N5 -> 35000 | Y20: ='CAPEX e Giro'!O5 -> 35000 | AA20: =C20+E20+G20+I20+K20+M20+O20+Q20+S20+U20+W20+Y20 -> 420000 | AB20: =AA20/$AA$7 -> 0.016102325
B21: (=) Geração de Caixa | C21: =C18-C19-C20 -> 104202.63 | E21: =E18-E19-E20 -> 207892.11 | G21: =G18-G19-G20 -> 208398.53 | I21: =I18-I19-I20 -> 256868.34 | K21: =K18-K19-K20 -> 280254.86 | M21: =M18-M19-M20 -> 353023.08 | O21: =O18-O19-O20 -> 337547.94 | Q21: =Q18-Q19-Q20 -> 481493.03 | S21: =S18-S19-S20 -> 495430.77 | U21: =U18-U19-U20 -> 533682.76 | W21: =W18-W19-W20 -> 619181.43 | Y21: =Y18-Y19-Y20 -> 616280.72 | AA21: =AA18-AA19-AA20 -> 4494256.2 | AB21: =AA21/$AA$7 -> 0.1723047
B22: (%) Margem Geração | C22: =C21/C7 -> 0.073505506 | E22: =E21/E7 -> 0.12927476 | G22: =G21/G7 -> 0.12521962 | I22: =I21/I7 -> 0.14137958 | K22: =K21/K7 -> 0.14093555 | M22: =M21/M7 -> 0.1711799 | O22: =O21/O7 -> 0.15099773 | Q22: =Q21/Q7 -> 0.19967905 | S22: =S21/S7 -> 0.20051874 | U22: =U21/U7 -> 0.20018214 | W22: =W21/W7 -> 0.2185942 | Y22: =Y21/Y7 -> 0.21182439
B24: Métricas Gerais
C25: Janeiro | D25: Realizado Jan | E25: Feveiro | G25: Março | I25: Abril | K25: Maio | M25: Junho | O25: Julho | Q25: Agosto | S25: Setembro | U25: Outubro | W25: Novembro | Y25: Dezembro
B26: Receita Total | C26: =C7-C8 -> 1332559.7 | E26: =E7-E8 -> 1511653 | G26: =G7-G8 -> 1564408.3 | I26: =I7-I8 -> 1707857.9 | K26: =K7-K8 -> 1869220.1 | M26: =M7-M8 -> 1938555.3 | O26: =O7-O8 -> 2101323.3 | Q26: =Q7-Q8 -> 2266654.6 | S26: =S7-S8 -> 2322500.7 | U26: =U7-U8 -> 2506026.8 | W26: =W7-W8 -> 2662607.4 | Y26: =Y7-Y8 -> 2734830.9
B27: Despesa Total | C27: =C9+C11+C15+C16+C19+C20+C12+C13 -> 1174357 | E27: =E9+E11+E15+E16+E19+E20+E12+E13 -> 1280760.9 | G27: =G9+G11+G15+G16+G19+G20+G12+G13 -> 1333009.8 | I27: =I9+I11+I15+I16+I19+I20+I12+I13 -> 1450989.6 | K27: =K9+K11+K15+K16+K19+K20+K12+K13 -> 1588965.3 | M27: =M9+M11+M15+M16+M19+M20+M12+M13 -> 1585532.2 | O27: =O9+O11+O15+O16+O19+O20+O12+O13 -> 1763775.4 | Q27: =Q9+Q11+Q15+Q16+Q19+Q20+Q12+Q13 -> 1785161.6 | S27: =S9+S11+S15+S16+S19+S20+S12+S13 -> 1827070 | U27: =U9+U11+U15+U16+U19+U20+U12+U13 -> 1972344 | W27: =W9+W11+W15+W16+W19+W20+W12+W13 -> 2043426 | Y27: =Y9+Y11+Y15+Y16+Y19+Y20+Y12+Y13 -> 2118550.2
B28: Vendas MRR | C28: =CAC!Q7 -> 215000 | E28: =CAC!R7 -> 215000 | G28: =CAC!S7 -> 215000 | I28: =CAC!T7 -> 240000 | K28: =CAC!U7 -> 240000 | M28: =CAC!V7 -> 240000 | O28: =CAC!W7 -> 270000 | Q28: =CAC!X7 -> 270000 | S28: =CAC!Y7 -> 270000 | U28: =CAC!Z7 -> 300000 | W28: =CAC!AA7 -> 300000 | Y28: =CAC!AB7 -> 300000
