Workbook

Sheet Anotações
B2: Documento auxiliar | D2: https://docs.google.com/document/d/1Bd9xdiEdrcTYg6vKJGJvyknFmdaPA3eUgVTLtH2r8Kg/edit?tab=t.0
B4: Definir quais eventos externos (CAC)
B5: Ações internas (eventos colaborador SG&A) | D5: Definir quais eventos
B7: Quais ferramentas precisamos desenvolver
B8: Produtos&Serviços gerais | F8: Conselho Consultivo | G8: Quais pessoas (Dudu, Omar, Simone?, Patrick?, Marcus Buaiz?, Angelo?, Fere?, Ulisses?, ), o que esperamos, qual remuneracao (% baixo ou pagar(quanto?)) , área (marketing, tech), qual frequencia (mensal/trimestral) etc
F9: TurbOOH | G9: CAPEX infinito, Payback esperado 4 meses,
F10: Deal com Agazeta
B11: Hugz | F11: Partnership de ações (tentar definir)
B12: Marketing de Rochas | F12: Distribuição
B14: Logo Chrun | C14: Chrun Receita | D14: NRR ou Net Churn | E14: Receita adicionada não ta sendo quebrada em nova e monetização (da bse)
B16: Participacoes em outras empresas e ventures
B17: Capex outras iniciativas
B19: Fazer painel de iniciativas e Projetos
B20: Fechar OKR Trimestre e KPIs de acompanhamento
B22: Deal com Maely
B23: Aporte Dudu
B25: Premiações
B26: Final do Ano | C26: 70% Spot (6 meses) | D26: 30% Premiação
B27: Semestral (Julho) | C27: 10-20 pessoas | D27: 6 meses
B28: Mensal | C28: Caju turbinado | D28: cafe da manha | E28: almoco equipe etc
B30: Distribuição = Caixa inicial + Geração de Caixa periodo - SALDO MINIMO CAIXA
B32: Comites:
B33: Produto*
B34: Gente e Gestao
B35: Financeiro
B36: Vendas
B37: Content

Sheet Overview
B2: Trimestre | C2: 1 Trimestre | F2: 2 Trimestre | I2: 3 Trimestre | L2: 4 Trimestre | R2: 1 Trimestre
B3: Mês | C3: Janeiro | D3: Feveiro | E3: Março | F3: Abril | G3: Maio | H3: Junho | I3: Julho | J3: Agosto | K3: Setembro | L3: Outubro | M3: Novembro | N3: Dezembro | O3: Total | R3: Inadimpência | S3: 0.06
B4: (+) MRR Ativo | C4: =Revenue!D5 -> 1155500 | D4: =Revenue!E5 -> 1251505 | E4: =Revenue!F5 -> 1338869.6 | F4: =Revenue!G5 -> 1438371.3 | G4: =Revenue!H5 -> 1528917.9 | H4: =Revenue!I5 -> 1611315.3 | I4: =Revenue!J5 -> 1706296.9 | J4: =Revenue!K5 -> 1792730.2 | ... N4: =Revenue!O5 -> 2122127.1 | O4: =sum(C4:N4) -> 19826271
B5: (+) Receita Pontual | C5: =Revenue!D37 -> 233333.33 | D5: =Revenue!E37 -> 266666.67 | E5: =Revenue!F37 -> 250000 | F5: =Revenue!G37 -> 266666.67 | G5: =Revenue!H37 -> 283333.33 | H5: =Revenue!I37 -> 300000 | I5: =Revenue!J37 -> 316666.67 | J5: =Revenue!K37 -> 333333.33 | ... N5: =Revenue!O37 -> 400000 | O5: =sum(C5:N5) -> 3750000 | R5: 2 Trimestre
B6: (+) Outras Receitas | C6: ='Outras Receitas'!C14 -> 23500 | D6: ='Outras Receitas'!D14 -> 23500 | E6: ='Outras Receitas'!E14 -> 23500 | F6: ='Outras Receitas'!F14 -> 24500 | G6: ='Outras Receitas'!G14 -> 24500 | H6: ='Outras Receitas'!H14 -> 24500 | I6: ='Outras Receitas'!I14 -> 30000 | J6: ='Outras Receitas'!J14 -> 30000 | ... N6: ='Outras Receitas'!N14 -> 31000 | O6: =sum(C6:N6) -> 327000 | R6: Inadimpência | S6: 0.06
B7: (=) Receita Total Faturavel | C7: =C4+C5+C6 -> 1412333.3 | D7: =D4+D5+D6 -> 1541671.7 | E7: =E4+E5+E6 -> 1612369.6 | F7: =F4+F5+F6 -> 1729538 | G7: =G4+G5+G6 -> 1836751.2 | H7: =H4+H5+H6 -> 1935815.3 | I7: =I4+I5+I6 -> 2052963.6 | J7: =J4+J5+J6 -> 2156063.5 | ... O7: =O4+O5+O6 -> 23903271
B8: (-) Inadimplência | C8: =C7*$S$3 -> 84740 | D8: =D7*$S$3 -> 92500.3 | E8: =E7*$S$3 -> 96742.173 | F8: =F7*$S$6 -> 103772.28 | G8: =G7*$S$6 -> 110205.07 | H8: =H7*$S$6 -> 116148.92 | I8: =I7*$S$9 -> 123177.81 | J8: =J7*$S$9 -> 129363.81 | K8: =K7*$S$9 -> 135083.07 | L8: =L7*$S$12 -> 141637.59 | M8: =M7*$S$12 -> 147637.61 | N8: =N7*$S$12 -> 153187.62 | O8: =sum(C8:N8) -> 1434196.3 | P8: =O8/$O$7 -> 0.06 | R8: 3 Trimestre
B9: (-) Impostos Sob Receita | C9: ='Tributário'!F11+'Tributário'!F12+'Tributário'!F13 -> 144599.01 | D9: ='Tributário'!G11+'Tributário'!G12+'Tributário'!G13 -> 157303.92 | E9: ='Tributário'!H11+'Tributário'!H12+'Tributário'!H13 -> 164248.57 | F9: ='Tributário'!I11+'Tributário'!I12+'Tributário'!I13 -> 175659.79 | G9: ='Tributário'!J11+'Tributário'!J12+'Tributário'!J13 -> 186191.35 | H9: ='Tributário'!K11+'Tributário'!K12+'Tributário'!K13 -> 195922.41 | I9: ='Tributário'!L11+'Tributário'!L12+'Tributário'!L13 -> 206889.62 | J9: ='Tributário'!M11+'Tributário'!M12+'Tributário'!M13 -> 217017.13 | ... N9: ='Tributário'!Q11+'Tributário'!Q12+'Tributário'!Q13 -> 255922.45 | O9: =sum(C9:N9) -> 2413984 | P9: =O9/$O$7 -> 0.1009897 | R9: Inadimpência | S9: 0.06
B10: (=) Receita Líquida | C10: =C7-C8-C9 -> 1182994.3 | D10: =D7-D8-D9 -> 1291867.5 | E10: =E7-E8-E9 -> 1351378.8 | F10: =F7-F8-F9 -> 1450105.9 | G10: =G7-G8-G9 -> 1540354.8 | H10: =H7-H8-H9 -> 1623743.9 | I10: =I7-I8-I9 -> 1722896.1 | J10: =J7-J8-J9 -> 1809682.6 | ... N10: =N7-N8-N9 -> 2144017 | O10: =sum(C10:N10) -> 20055091 | Q10: =O10/$O$7 -> 0.8390103
B11: (-) CSV | C11: =CSV!D4 -> 390210 | D11: =CSV!E4 -> 405289.6 | E11: =CSV!F4 -> 433909.54 | F11: =CSV!G4 -> 473038.68 | G11: =CSV!H4 -> 494658.2 | H11: =CSV!I4 -> 517586.96 | I11: =CSV!J4 -> 577042.13 | J11: =CSV!K4 -> 601503.34 | ... N11: =CSV!O4 -> 695130.16 | O11: =sum(C11:N11) -> 6556472.8 | P11: =O11/$O$7 -> 0.27429187 | R11: 4 Trimestre
B12: (=) Lucro Bruto | C12: =C10-C11 -> 792784.32 | D12: =D10-D11 -> 886577.85 | E12: =E10-E11 -> 917469.27 | F12: =F10-F11 -> 977067.21 | G12: =G10-G11 -> 1045696.6 | H12: =H10-H11 -> 1106157 | I12: =I10-I11 -> 1145854 | J12: =J10-J11 -> 1208179.2 | ... N12: =N10-N11 -> 1448886.8 | O12: =sum(C12:N12) -> 13498618 | Q12: =O12/$O$7 -> 0.56471844 | R12: Inadimpência | S12: 0.06
B13: (-) CAC | C13: =CAC!C6 -> 285217.02 | D13: =CAC!D6 -> 288717.02 | E13: =CAC!E6 -> 314717.02 | F13: =CAC!F6 -> 332957.07 | G13: =CAC!G6 -> 417957.07 | H13: =CAC!H6 -> 357957.07 | I13: =CAC!I6 -> 442197.13 | J13: =CAC!J6 -> 360197.13 | ... N13: =CAC!N6 -> 417437.19 | O13: =sum(C13:N13) -> 4376925.2 | P13: =O13/$O$7 -> 0.18310989
B14: (-) SG&A | C14: ='SG&A'!C6 -> 402130 | D14: ='SG&A'!D6 -> 280477 | E14: ='SG&A'!E6 -> 279518 | F14: ='SG&A'!F6 -> 285633 | G14: ='SG&A'!G6 -> 288429 | H14: ='SG&A'!H6 -> 293174 | I14: ='SG&A'!I6 -> 433887 | J14: ='SG&A'!J6 -> 305132 | ... N14: ='SG&A'!N6 -> 346886 | O14: =sum(C14:N14) -> 3851925 | P14: =O14/$O$7 -> 0.16114636
B15: (=) EBITDA | C15: =C12-C13-C14 -> 105437.31 | D15: =D12-D13-D14 -> 317383.84 | E15: =E12-E13-E14 -> 323234.26 | F15: =F12-F13-F14 -> 358477.14 | G15: =G12-G13-G14 -> 339310.52 | H15: =H12-H13-H14 -> 455025.91 | I15: =I12-I13-I14 -> 269769.86 | J15: =J12-J13-J14 -> 542850.09 | ... N15: =N12-N13-N14 -> 684563.63 | O15: =sum(C15:N15) -> 5269767.6 | Q15: =O15/$O$7 -> 0.2204622
B16: (-) IR + CSLL | C16: ='Tributário'!F14 -> 35848.684 | D16: ='Tributário'!G14 -> 107910.5 | E16: ='Tributário'!H14 -> 109899.65 | F16: ='Tributário'!I14 -> 121882.23 | G16: ='Tributário'!J14 -> 115365.58 | H16: ='Tributário'!K14 -> 154708.81 | I16: ='Tributário'!L14 -> 91721.752 | J16: ='Tributário'!M14 -> 184569.03 | ... N16: ='Tributário'!Q14 -> 232751.63 | O16: =sum(C16:N16) -> 1791721 | P16: =O16/$O$7 -> 0.074957146
B17: (-) CAPEX | C17: ='CAPEX e Giro'!D5 -> 32500 | D17: ='CAPEX e Giro'!E5 -> 32500 | E17: ='CAPEX e Giro'!F5 -> 32500 | F17: ='CAPEX e Giro'!G5 -> 32500 | G17: ='CAPEX e Giro'!H5 -> 32500 | H17: ='CAPEX e Giro'!I5 -> 32500 | I17: ='CAPEX e Giro'!J5 -> 32500 | J17: ='CAPEX e Giro'!K5 -> 32500 | ... N17: ='CAPEX e Giro'!O5 -> 32500 | O17: =sum(C17:N17) -> 390000 | P17: =O17/$O$7 -> 0.016315759
B18: (=) Geração de Caixa | C18: =C15-C16-C17 -> 37088.622 | D18: =D15-D16-D17 -> 176973.33 | E18: =E15-E16-E17 -> 180834.61 | F18: =F15-F16-F17 -> 204094.91 | G18: =G15-G16-G17 -> 191444.94 | H18: =H15-H16-H17 -> 267817.1 | I18: =I15-I16-I17 -> 145548.11 | J18: =J15-J16-J17 -> 325781.06 | ... O18: =O15-O16-O17 -> 3088046.6 | P18: =O18/$O$7 -> 0.12918929
B19: (%) Margem Geração | C19: =C18/C4 -> 0.032097466 | D19: =D18/D4 -> 0.14140841 | E19: =E18/E4 -> 0.13506514 | F19: =F18/F4 -> 0.14189307 | G19: =G18/G4 -> 0.12521597 | H19: =H18/H4 -> 0.16621024 | I19: =I18/I4 -> 0.085300576 | J19: =J18/J4 -> 0.18172342 | ... N19: =N18/N4 -> 0.19759043
B21: Métricas Gerais
B22: Receita Total | C22: =C7 -> 1412333.3 | D22: =D7 -> 1541671.7 | E22: =E7 -> 1612369.6 | F22: =F7 -> 1729538 | G22: =G7 -> 1836751.2 | H22: =H7 -> 1935815.3 | I22: =I7 -> 2052963.6 | J22: =J7 -> 2156063.5 | ... N22: =N7 -> 2553127.1
B23: Despesa Total | C23: =C9+C11+C13+C14+C16+C17 -> 1290504.7 | D23: =D9+D11+D13+D14+D16+D17 -> 1272198 | E23: =E9+E11+E13+E14+E16+E17 -> 1334792.8 | F23: =F9+F11+F13+F14+F16+F17 -> 1421670.8 | G23: =G9+G11+G13+G14+G16+G17 -> 1535101.2 | H23: =H9+H11+H13+H14+H16+H17 -> 1551849.3 | I23: =I9+I11+I13+I14+I16+I17 -> 1784237.6 | J23: =J9+J11+J13+J14+J16+J17 -> 1700918.6 | ... N23: =N9+N11+N13+N14+N16+N17 -> 1980627.4
B24: Vendas MRR | C24: =CAC!Q6 -> 200000 | D24: =CAC!R6 -> 200000 | E24: =CAC!S6 -> 200000 | F24: =CAC!T6 -> 220000 | G24: =CAC!U6 -> 220000 | H24: =CAC!V6 -> 220000 | I24: =CAC!W6 -> 240000 | J24: =CAC!X6 -> 240000 | ... N24: =CAC!AB6 -> 260000
B25: Vendas Pontual | C25: =CAC!Q35 -> 250000 | D25: =CAC!R35 -> 250000 | E25: =CAC!S35 -> 250000 | F25: =CAC!T35 -> 300000 | G25: =CAC!U35 -> 300000 | H25: =CAC!V35 -> 300000 | I25: =CAC!W35 -> 350000 | J25: =CAC!X35 -> 350000 | ... N25: =CAC!AB35 -> 400000
B26: Numero de Colaboradores | C26: =CSV!D7+count('SG&A'!C20:C22)+count('SG&A'!C28:C37)+count(CAC!C21:C38)+count(CAC!C44:C60)+count(CAC!C66:C71)+count(CAC!C77:C86) -> 126 | D26: =CSV!E7+count('SG&A'!D20:D22)+count('SG&A'!D28:D37)+count(CAC!D21:D38)+count(CAC!D44:D60)+count(CAC!D66:D71)+count(CAC!D77:D86) -> 129 | E26: =CSV!F7+count('SG&A'!E20:E22)+count('SG&A'!E28:E37)+count(CAC!E21:E38)+count(CAC!E44:E60)+count(CAC!E66:E71)+count(CAC!E77:E86) -> 138 | F26: =CSV!G7+count('SG&A'!F20:F22)+count('SG&A'!F28:F37)+count(CAC!F21:F38)+count(CAC!F44:F60)+count(CAC!F66:F71)+count(CAC!F77:F86) -> 143 | G26: =CSV!H7+count('SG&A'!G20:G22)+count('SG&A'!G28:G37)+count(CAC!G21:G38)+count(CAC!G44:G60)+count(CAC!G66:G71)+count(CAC!G77:G86) -> 147 | H26: =CSV!I7+count('SG&A'!H20:H22)+count('SG&A'!H28:H37)+count(CAC!H21:H38)+count(CAC!H44:H60)+count(CAC!H66:H71)+count(CAC!H77:H86) -> 152 | I26: =CSV!J7+count('SG&A'!I20:I22)+count('SG&A'!I28:I37)+count(CAC!I21:I38)+count(CAC!I44:I60)+count(CAC!I66:I71)+count(CAC!I77:I86) -> 159 | J26: =CSV!K7+count('SG&A'!J20:J22)+count('SG&A'!J28:J37)+count(CAC!J21:J38)+count(CAC!J44:J60)+count(CAC!J66:J71)+count(CAC!J77:J86) -> 164 | ... N26: =CSV!O7+count('SG&A'!N20:N22)+count('SG&A'!N28:N37)+count(CAC!N21:N38)+count(CAC!N44:N60)+count(CAC!N66:N71)+count(CAC!N77:N86) -> 180
B27: Receita Cabeça | C27: =C7/C26 -> 11208.995 | D27: =D7/D26 -> 11950.943 | E27: =E7/E26 -> 11683.837 | F27: =F7/F26 -> 12094.671 | G27: =G7/G26 -> 12494.906 | H27: =H7/H26 -> 12735.627 | I27: =I7/I26 -> 12911.72 | J27: =J7/J26 -> 13146.729 | ... N27: =N7/N26 -> 14184.039
B28: MRR Cabeça | C28: =C4/C26 -> 9170.6349 | D28: =D4/D26 -> 9701.5891 | E28: =E4/E26 -> 9701.9533 | F28: =F4/F26 -> 10058.54 | G28: =G4/G26 -> 10400.802 | H28: =H4/H26 -> 10600.758 | I28: =I4/I26 -> 10731.427 | J28: =J4/J26 -> 10931.282 | ... N28: =N4/N26 -> 11789.595
B29: Numero de Clientes | C29: =C30/1.43 -> 305.51948 | D29: =D30/1.43 -> 328.90175 | E29: =E30/1.43 -> 345.55039 | F29: =F30/1.43 -> 365.93873 | G29: =G30/1.43 -> 384.94668 | H29: =H30/1.43 -> 401.29015 | I29: =I30/1.43 -> 421.42637 | J29: =J30/1.43 -> 440.21452 | ... N29: =N30/1.43 -> 511.04955
B30: Numero de Contratos | C30: =CSV!C12+CSV!C85+CSV!C141+CSV!C202+CSV!C225+CAC!Q39+CAC!Q44+CAC!Q49+CAC!Q54+CAC!Q59+CAC!Q64 -> 436.89286 | D30: =CSV!D12+CSV!D85+CSV!D141+CSV!D202+CSV!D225+CAC!R39+CAC!R44+CAC!R49+CAC!R54+CAC!R59+CAC!R64 -> 470.3295 | E30: =CSV!E12+CSV!E85+CSV!E141+CSV!E202+CSV!E225+CAC!S39+CAC!S44+CAC!S49+CAC!S54+CAC!S59+CAC!S64 -> 494.13706 | F30: =CSV!F12+CSV!F85+CSV!F141+CSV!F202+CSV!F225+CAC!T39+CAC!T44+CAC!T49+CAC!T54+CAC!T59+CAC!T64 -> 523.29238 | G30: =CSV!G12+CSV!G85+CSV!G141+CSV!G202+CSV!G225+CAC!U39+CAC!U44+CAC!U49+CAC!U54+CAC!U59+CAC!U64 -> 550.47376 | H30: =CSV!H12+CSV!H85+CSV!H141+CSV!H202+CSV!H225+CAC!V39+CAC!V44+CAC!V49+CAC!V54+CAC!V59+CAC!V64 -> 573.84491 | I30: =CSV!I12+CSV!I85+CSV!I141+CSV!I202+CSV!I225+CAC!W39+CAC!W44+CAC!W49+CAC!W54+CAC!W59+CAC!W64 -> 602.63971 | J30: =CSV!J12+CSV!J85+CSV!J141+CSV!J202+CSV!J225+CAC!X39+CAC!X44+CAC!X49+CAC!X54+CAC!X59+CAC!X64 -> 629.50677 | ... N30: =CSV!N12+CSV!N85+CSV!N141+CSV!N202+CSV!N225+CAC!AB39+CAC!AB44+CAC!AB49+CAC!AB54+CAC!AB59+CAC!AB64 -> 730.80086
B31: Ticket Medio Cliente | C31: =C7/C29 -> 4622.7276 | D31: =D7/D29 -> 4687.3319 | E31: =E7/E29 -> 4666.0909 | F31: =F7/F29 -> 4726.3048 | G31: =G7/G29 -> 4771.4431 | H31: =H7/H29 -> 4823.979 | I31: =I7/I29 -> 4871.4644 | J31: =J7/J29 -> 4897.7564 | ... N31: =N7/N29 -> 4995.8503
B32: Ticket Medio Contratos | C32: =C7/C30 -> 3232.6766 | D32: =D7/D30 -> 3277.8545 | E32: =E7/E30 -> 3263.0006 | F32: =F7/F30 -> 3305.1082 | G32: =G7/G30 -> 3336.6735 | H32: =H7/H30 -> 3373.4119 | I32: =I7/I30 -> 3406.6184 | J32: =J7/J30 -> 3425.0045 | ... N32: =N7/N30 -> 3493.6016
B33: Churn Mês | C33: =Revenue!D32 -> 103995 | D33: =Revenue!E32 -> 112635.45 | E33: =Revenue!F32 -> 120498.26 | F33: =Revenue!G32 -> 129453.42 | G33: =Revenue!H32 -> 137602.61 | H33: =Revenue!I32 -> 145018.37 | I33: =Revenue!J32 -> 153566.72 | J33: =Revenue!K32 -> 161345.72 | ... N33: =Revenue!O32 -> 190991.43
B34: Aliquota Imposto Efetiva | C34: =(C16+C9)/C7 -> 0.12776566 | D34: =(D16+D9)/D7 -> 0.17203042 | E34: =(E16+E9)/E7 -> 0.17002815 | F34: =(F16+F9)/F7 -> 0.17203555 | G34: =(G16+G9)/G7 -> 0.16417952 | H34: =(H16+H9)/H7 -> 0.18112845 | I34: =(I16+I9)/I7 -> 0.14545381 | J34: =(J16+J9)/J7 -> 0.18625897 | ... N34: =(N16+N9)/N7 -> 0.19140218
B35: Geracao de caixa | C35: =C18 -> 37088.622 | D35: =D18 -> 176973.33 | E35: =E18 -> 180834.61 | F35: =F18 -> 204094.91 | G35: =G18 -> 191444.94 | H35: =H18 -> 267817.1 | I35: =I18 -> 145548.11 | J35: =J18 -> 325781.06 | ... N35: =N18 -> 419311.99
B36: Margem de geração | C36: =C19 -> 0.032097466 | D36: =D19 -> 0.14140841 | E36: =E19 -> 0.13506514 | F36: =F19 -> 0.14189307 | G36: =G19 -> 0.12521597 | H36: =H19 -> 0.16621024 | I36: =I19 -> 0.085300576 | J36: =J19 -> 0.18172342 | ... N36: =N19 -> 0.19759043
B37: Saldo de Caixa | C37: =650000+C35 -> 687088.62 | D37: =C37+D35 -> 864061.95 | E37: =D37+E35 -> 1044896.6 | F37: =E37+F35 -> 1248991.5 | G37: =F37+G35 -> 1440436.4 | H37: =G37+H35 -> 1708253.5 | I37: =H37+I35 -> 1853801.6 | J37: =I37+J35 -> 2179582.7 | K37: =J37+K35 -> 2533847.8 | ... N37: =M37+N35 -> 3738046.6
B39: Numero de Colaboradores | C39: =CSV!D7+count('SG&A'!C20:C22)+count('SG&A'!C28:C37)+count(CAC!C21:C38)+count(CAC!C44:C60)+count(CAC!C66:C71)+count(CAC!C77:C86) -> 126 | D39: =CSV!E7+count('SG&A'!D20:D22)+count('SG&A'!D28:D37)+count(CAC!D21:D38)+count(CAC!D44:D60)+count(CAC!D66:D71)+count(CAC!D77:D86) -> 129 | E39: =CSV!F7+count('SG&A'!E20:E22)+count('SG&A'!E28:E37)+count(CAC!E21:E38)+count(CAC!E44:E60)+count(CAC!E66:E71)+count(CAC!E77:E86) -> 138 | F39: =CSV!G7+count('SG&A'!F20:F22)+count('SG&A'!F28:F37)+count(CAC!F21:F38)+count(CAC!F44:F60)+count(CAC!F66:F71)+count(CAC!F77:F86) -> 143 | G39: =CSV!H7+count('SG&A'!G20:G22)+count('SG&A'!G28:G37)+count(CAC!G21:G38)+count(CAC!G44:G60)+count(CAC!G66:G71)+count(CAC!G77:G86) -> 147 | H39: =CSV!I7+count('SG&A'!H20:H22)+count('SG&A'!H28:H37)+count(CAC!H21:H38)+count(CAC!H44:H60)+count(CAC!H66:H71)+count(CAC!H77:H86) -> 152 | I39: =CSV!J7+count('SG&A'!I20:I22)+count('SG&A'!I28:I37)+count(CAC!I21:I38)+count(CAC!I44:I60)+count(CAC!I66:I71)+count(CAC!I77:I86) -> 159 | J39: =CSV!K7+count('SG&A'!J20:J22)+count('SG&A'!J28:J37)+count(CAC!J21:J38)+count(CAC!J44:J60)+count(CAC!J66:J71)+count(CAC!J77:J86) -> 164 | ... N39: =CSV!O7+count('SG&A'!N20:N22)+count('SG&A'!N28:N37)+count(CAC!N21:N38)+count(CAC!N44:N60)+count(CAC!N66:N71)+count(CAC!N77:N86) -> 180
B40: Pessoas em CSV | C40: =CSV!D7 -> 87 | D40: =CSV!E7 -> 89 | E40: =CSV!F7 -> 96 | F40: =CSV!G7 -> 100 | G40: =CSV!H7 -> 104 | H40: =CSV!I7 -> 108 | I40: =CSV!J7 -> 115 | J40: =CSV!K7 -> 119 | ... N40: =CSV!O7 -> 132
B41: Pessoas em CAC | C41: =CAC!C5 -> 27 | D41: =CAC!D5 -> 28 | E41: =CAC!E5 -> 30 | F41: =CAC!F5 -> 31 | G41: =CAC!G5 -> 31 | H41: =CAC!H5 -> 31 | I41: =CAC!I5 -> 31 | J41: =CAC!J5 -> 32 | ... N41: =CAC!N5 -> 35
B42: Pessoas em SGEA | C42: ='SG&A'!C5 -> 12 | D42: ='SG&A'!D5 -> 12 | E42: ='SG&A'!E5 -> 12 | F42: ='SG&A'!F5 -> 12 | G42: ='SG&A'!G5 -> 12 | H42: ='SG&A'!H5 -> 13 | I42: ='SG&A'!I5 -> 13 | J42: ='SG&A'!J5 -> 13 | ... N42: ='SG&A'!N5 -> 13

Sheet SG&A
B2: CSV
B3: Trimestre | C3: 1 Trimestre | F3: 2 Trimestre | I3: 3 Trimestre | L3: 4 Trimestre
B4: Mês | C4: Janeiro | D4: Feveiro | E4: Março | F4: Abril | G4: Maio | H4: Junho | I4: Julho | J4: Agosto | K4: Setembro | L4: Outubro | M4: Novembro | N4: Dezembro
B5: Pessoas Totais Commerce (CSV) | C5: =count(C20:C22)+count(C28:C37) -> 12 | D5: =count(D20:D22)+count(D28:D37) -> 12 | E5: =count(E20:E22)+count(E28:E37) -> 12 | F5: =count(F20:F22)+count(F28:F37) -> 12 | G5: =count(G20:G22)+count(G28:G37) -> 12 | H5: =count(H20:H22)+count(H28:H37) -> 13 | I5: =count(I20:I22)+count(I28:I37) -> 13 | J5: =count(J20:J22)+count(J28:J37) -> 13 | ... N5: =count(N20:N22)+count(N28:N37) -> 13
B6: (=) SG&A | C6: =SUM(C7:C14) -> 402130 | D6: =SUM(D7:D14) -> 280477 | E6: =SUM(E7:E14) -> 279518 | F6: =SUM(F7:F14) -> 285633 | G6: =SUM(G7:G14) -> 288429 | H6: =SUM(H7:H14) -> 293174 | I6: =SUM(I7:I14) -> 433887 | J6: =SUM(J7:J14) -> 305132 | ... N6: =SUM(N7:N14) -> 346886
B7: (-) UZK | C7: =C19 -> 80000 | D7: =D19 -> 80000 | E7: =E19 -> 80000 | F7: =F19 -> 80000 | G7: =G19 -> 80000 | H7: =H19 -> 80000 | I7: =I19 -> 80000 | J7: =J19 -> 80000 | ... N7: =N19 -> 80000
B8: (-) Backoffice | C8: =C27 -> 49500 | D8: =D27 -> 49500 | E8: =E27 -> 49500 | F8: =F27 -> 51000 | G8: =G27 -> 52000 | H8: =H27 -> 54500 | I8: =I27 -> 57500 | J8: =J27 -> 57500 | ... N8: =N27 -> 60500
B9: (-) Software | C9: =C42 -> 34324 | D9: =D42 -> 34471 | E9: =E42 -> 34912 | F9: =F42 -> 37027 | G9: =G42 -> 37223 | H9: =H42 -> 37468 | I9: =I42 -> 56881 | J9: =J42 -> 43126 | ... N9: =N42 -> 44980
B10: (-) Ocupação | C10: =C57 -> 44570 | D10: =D57 -> 39570 | E10: =E57 -> 34570 | F10: =F57 -> 34570 | G10: =G57 -> 34570 | H10: =H57 -> 34570 | I10: =I57 -> 34570 | J10: =J57 -> 29570 | ... N10: =N57 -> 29570
B11: (-) Beneficio Caju | C11: =Overview!C26*400 -> 50400 | D11: =Overview!D26*400 -> 51600 | E11: =Overview!E26*400 -> 55200 | F11: =Overview!F26*400 -> 57200 | G11: =Overview!G26*400 -> 58800 | H11: =Overview!H26*400 -> 60800 | I11: =Overview!I26*400 -> 63600 | J11: =Overview!J26*400 -> 65600 | ... N11: =Overview!N26*400 -> 72000
B12: (-) Premiações | C12: 100000 | D12: 5000 | E12: 5000 | F12: 5000 | G12: 5000 | H12: 5000 | I12: 120000 | J12: 5000 | K12: 5000 | L12: 5000 | M12: 5000 | N12: 5000
B13: (-) Eventos e Brindes Internos | C13: 30000 | D13: 7000 | E13: 7000 | F13: 7000 | G13: 7000 | H13: 7000 | I13: 7000 | J13: 10000 | K13: 10000 | L13: 10000 | M13: 10000 | N13: 40000
B14: (-) Outras despesas | C14: =C68 -> 13336 | D14: =D68 -> 13336 | E14: =E68 -> 13336 | F14: =F68 -> 13836 | G14: =G68 -> 13836 | H14: =H68 -> 13836 | I14: =I68 -> 14336 | J14: =J68 -> 14336 | ... N14: =N68 -> 14836
B16: UZK
B17: Trimestre | C17: 1 Trimestre | F17: 2 Trimestre | I17: 3 Trimestre | L17: 4 Trimestre
B18: Mês | C18: Janeiro | D18: Feveiro | E18: Março | F18: Abril | G18: Maio | H18: Junho | I18: Julho | J18: Agosto | K18: Setembro | L18: Outubro | M18: Novembro | N18: Dezembro
B19: (=) UZK | C19: =SUM(C20:C22) -> 80000 | D19: =SUM(D20:D22) -> 80000 | E19: =SUM(E20:E22) -> 80000 | F19: =SUM(F20:F22) -> 80000 | G19: =SUM(G20:G22) -> 80000 | H19: =SUM(H20:H22) -> 80000 | I19: =SUM(I20:I22) -> 80000 | J19: =SUM(J20:J22) -> 80000 | ... N19: =SUM(N20:N22) -> 80000
B20: (-) Victor Peixoto | C20: 30000 | D20: 30000 | E20: 30000 | F20: 30000 | G20: 30000 | H20: 30000 | I20: 30000 | J20: 30000 | K20: 30000 | L20: 30000 | M20: 30000 | N20: 30000
B21: (-) Rodrigo Queiroz | C21: 25000 | D21: 25000 | E21: 25000 | F21: 25000 | G21: 25000 | H21: 25000 | I21: 25000 | J21: 25000 | K21: 25000 | L21: 25000 | M21: 25000 | N21: 25000
B22: (-) André Musso | C22: 25000 | D22: 25000 | E22: 25000 | F22: 25000 | G22: 25000 | H22: 25000 | I22: 25000 | J22: 25000 | K22: 25000 | L22: 25000 | M22: 25000 | N22: 25000
B24: Backoffice
B25: Trimestre | C25: 1 Trimestre | F25: 2 Trimestre | I25: 3 Trimestre | L25: 4 Trimestre
B26: Mês | C26: Janeiro | D26: Feveiro | E26: Março | F26: Abril | G26: Maio | H26: Junho | I26: Julho | J26: Agosto | K26: Setembro | L26: Outubro | M26: Novembro | N26: Dezembro
B27: (=) Backoffice | C27: =SUM(C28:C37) -> 49500 | D27: =SUM(D28:D37) -> 49500 | E27: =SUM(E28:E37) -> 49500 | F27: =SUM(F28:F37) -> 51000 | G27: =SUM(G28:G37) -> 52000 | H27: =SUM(H28:H37) -> 54500 | I27: =SUM(I28:I37) -> 57500 | J27: =SUM(J28:J37) -> 57500 | ... N27: =SUM(N28:N37) -> 60500
B28: (-) Marlon Carneiro | C28: 7000 | D28: 7000 | E28: 7000 | F28: 7500 | G28: 7500 | H28: 7500 | I28: 7500 | J28: 7500 | K28: 7500 | L28: 7500 | M28: 7500 | N28: 7500
B29: (-) Warley Pablo | C29: 3500 | D29: 3500 | E29: 3500 | F29: 3500 | G29: 3500 | H29: 3500 | I29: 4000 | J29: 4000 | K29: 4000 | L29: 4000 | M29: 4000 | N29: 4000
B30: (-) Eduardo Tonane | C30: 2000 | D30: 2000 | E30: 2000 | F30: 2000 | G30: 3000 | H30: 3000 | I30: 3000 | J30: 3000 | K30: 3000 | L30: 3500 | M30: 3500 | N30: 3500
B31: (-) Karol Tognere | C31: 7000 | D31: 7000 | E31: 7000 | F31: 7000 | G31: 7000 | H31: 7000 | I31: 7500 | J31: 7500 | K31: 7500 | L31: 7500 | M31: 7500 | N31: 7500
B32: (-) Lianca Lopes | C32: 3500 | D32: 3500 | E32: 3500 | F32: 4000 | G32: 4000 | H32: 4000 | I32: 4500 | J32: 4500 | K32: 4500 | L32: 4500 | M32: 4500 | N32: 4500
B33: (-) Caio Massaroni | C33: 7000 | D33: 7000 | E33: 7000 | F33: 7000 | G33: 7000 | H33: 7000 | I33: 8000 | J33: 8000 | K33: 8000 | L33: 8000 | M33: 8000 | N33: 8000
B34: (-) Thiago Folador | C34: 6500 | D34: 6500 | E34: 6500 | F34: 7000 | G34: 7000 | H34: 7000 | I34: 7000 | J34: 7000 | K34: 7000 | L34: 7000 | M34: 7000 | N34: 7000
B35: (-) Julia Viana | C35: 6000 | D35: 6000 | E35: 6000 | F35: 6000 | G35: 6000 | H35: 6000 | I35: 6500 | J35: 6500 | K35: 6500 | L35: 6500 | M35: 6500 | N35: 6500
B36: (-) Marcelus | C36: 7000 | D36: 7000 | E36: 7000 | F36: 7000 | G36: 7000 | H36: 7500 | I36: 7500 | J36: 7500 | K36: 7500 | L36: 8000 | M36: 8000 | N36: 8000
B37: Nova contratação 5 | H37: 2000 | I37: 2000 | J37: 2000 | K37: 2000 | L37: 4000 | M37: 4000 | N37: 4000
B39: Software
B40: Trimestre | C40: 1 Trimestre | F40: 2 Trimestre | I40: 3 Trimestre | L40: 4 Trimestre
B41: Mês | C41: Janeiro | D41: Feveiro | E41: Março | F41: Abril | G41: Maio | H41: Junho | I41: Julho | J41: Agosto | K41: Setembro | L41: Outubro | M41: Novembro | N41: Dezembro
B42: (=) Software | C42: =SUM(C43:C52) -> 34324 | D42: =SUM(D43:D52) -> 34471 | E42: =SUM(E43:E52) -> 34912 | F42: =SUM(F43:F52) -> 37027 | G42: =SUM(G43:G52) -> 37223 | H42: =SUM(H43:H52) -> 37468 | I42: =SUM(I43:I52) -> 56881 | J42: =SUM(J43:J52) -> 43126 | ... N42: =SUM(N43:N52) -> 44980
B43: GohighLevel | C43: 5000 | D43: 5000 | E43: 5000 | F43: 5000 | G43: 5000 | H43: 5000 | I43: 5000 | J43: 5000 | K43: 5000 | L43: 5000 | M43: 5000 | N43: 5000
B44: Adobe | C44: 2700 | D44: 2700 | E44: 2700 | F44: 3500 | G44: 3500 | H44: 3500 | I44: 4000 | J44: 4000 | K44: 4000 | L44: 4500 | M44: 4500 | N44: 4500
...

Sheet CSV
C2: Commerce
C3: Mês | D3: Janeiro | E3: Feveiro | F3: Março | G3: Abril | H3: Maio | I3: Junho | J3: Julho | K3: Agosto | L3: Setembro | M3: Outubro | N3: Novembro | O3: Dezembro
C4: CSV Total | D4: =D24+D96+D152+D213+D236+D124+D182+D64+D265+D295+D322+D342 -> 390210 | E4: =E24+E96+E152+E213+E236+E124+E182+E64+E265+E295+E322+E342 -> 405289.6 | F4: =F24+F96+F152+F213+F236+F124+F182+F64+F265+F295+F322+F342 -> 433909.54 | G4: =G24+G96+G152+G213+G236+G124+G182+G64+G265+G295+G322+G342 -> 473038.68 | H4: =H24+H96+H152+H213+H236+H124+H182+H64+H265+H295+H322+H342 -> 494658.2 | I4: =I24+I96+I152+I213+I236+I124+I182+I64+I265+I295+I322+I342 -> 517586.96 | J4: =J24+J96+J152+J213+J236+J124+J182+J64+J265+J295+J322+J342 -> 577042.13 | K4: =K24+K96+K152+K213+K236+K124+K182+K64+K265+K295+K322+K342 -> 601503.34 | ... O4: =O24+O96+O152+O213+O236+O124+O182+O64+O265+O295+O322+O342 -> 695130.16
C5: Quantidade de operadores | D5: =D15+D144+D205+D228+D88+D228+D117+D175+D57+D258+D313 -> 81 | E5: =E15+E144+E205+E228+E88+E228+E117+E175+E57+E258+E313 -> 83 | F5: =F15+F144+F205+F228+F88+F228+F117+F175+F57+F258+F313 -> 89 | G5: =G15+G144+G205+G228+G88+G228+G117+G175+G57+G258+G313 -> 93 | H5: =H15+H144+H205+H228+H88+H228+H117+H175+H57+H258+H313 -> 96 | I5: =I15+I144+I205+I228+I88+I228+I117+I175+I57+I258+I313 -> 100 | J5: =J15+J144+J205+J228+J88+J228+J117+J175+J57+J258+J313 -> 106 | K5: =K15+K144+K205+K228+K88+K228+K117+K175+K57+K258+K313 -> 110 | ... O5: =O15+O144+O205+O228+O88+O228+O117+O175+O57+O258+O313 -> 122
C6: Quantidade de Líderes | D6: =D286 -> 6 | E6: =E286 -> 6 | F6: =F286 -> 7 | G6: =G286 -> 7 | H6: =H286 -> 8 | I6: =I286 -> 8 | J6: =J286 -> 9 | K6: =K286 -> 9 | ... O6: =O286 -> 10
C7: Pessoas Totais Commerce (CSV) | D7: =D5+D6 -> 87 | E7: =E5+E6 -> 89 | F7: =F5+F6 -> 96 | G7: =G5+G6 -> 100 | H7: =H5+H6 -> 104 | I7: =I5+I6 -> 108 | J7: =J5+J6 -> 115 | K7: =K5+K6 -> 119 | ... O7: =O5+O6 -> 132
B9: Performance
B10: Mês | C10: Dezembro | D10: Janeiro | E10: Feveiro | F10: Março | G10: Abril | H10: Maio | I10: Junho | J10: Julho | K10: Agosto | L10: Setembro | M10: Outubro | N10: Novembro | O10: Dezembro
B11: MRR Performance | C11: =Revenue!C7 -> 475000 | D11: =Revenue!D7 -> 492250 | E11: =Revenue!E7 -> 507947.5 | F11: =Revenue!F7 -> 522232.22 | G11: =Revenue!G7 -> 541231.32 | H11: =Revenue!H7 -> 558520.51 | I11: =Revenue!I7 -> 574253.66 | J11: =Revenue!J7 -> 594570.83 | ... O11: =Revenue!O7 -> 688234.19 | P11: =SUM(D11:O11) -> 7043965.4
B12: Contratos Performance | C12: =Revenue!C9 -> 170 | D12: =Revenue!D9 -> 174.81776 | E12: =Revenue!E9 -> 179.18912 | F12: =Revenue!F9 -> 183.15598 | G12: =Revenue!G9 -> 188.76361 | H12: =Revenue!H9 -> 193.8566 | I12: =Revenue!I9 -> 198.48258 | J12: =Revenue!J9 -> 204.68999 | ... O12: =Revenue!O9 -> 233.68641
B13: Capacity Contratos | C13: 12 | D13: 12 | E13: 12 | F13: 12 | G13: 12 | H13: 12 | I13: 12 | J13: 12 | K13: 12 | L13: 12 | M13: 12 | N13: 12 | O13: 12
B14: Operadores Necessários | C14: =C12/C13 -> 14.166667 | D14: =D12/D13 -> 14.568146 | E14: =E12/E13 -> 14.932427 | F14: =F12/F13 -> 15.262998 | G14: =G12/G13 -> 15.730301 | H14: =H12/H13 -> 16.154717 | I14: =I12/I13 -> 16.540215 | J14: =J12/J13 -> 17.057499 | ... O14: =O12/O13 -> 19.473867
B15: Operadores Atuais | C15: 15 | D15: =count(D25:D50) -> 18 | E15: =count(E25:E50) -> 19 | F15: =count(F25:F50) -> 20 | G15: =count(G25:G50) -> 20 | H15: =count(H25:H50) -> 21 | I15: =count(I25:I50) -> 21 | J15: =count(J25:J50) -> 22 | K15: =count(K25:K50) -> 22 | ... O15: =count(O25:O50) -> 25
B16: Necessidade de contratar | C16: =C14-C15 -> -0.83333333 | D16: =D14-D15 -> -3.4318536 | E16: =E14-E15 -> -4.0675732 | F16: =F14-F15 -> -4.737002 | G16: =G14-G15 -> -4.2696989 | H16: =H14-H15 -> -4.8452833 | I16: =I14-I15 -> -4.4597848 | J16: =J14-J15 -> -4.942501 | ... O16: =O14-O15 -> -5.5261328
B17: Contratos por gestor | C17: =C12/C15 -> 11.333333 | D17: =D12/D15 -> 9.7120976 | E17: =E12/E15 -> 9.4310064 | F17: =F12/F15 -> 9.1577988 | G17: =G12/G15 -> 9.4381807 | H17: =H12/H15 -> 9.2312667 | I17: =I12/I15 -> 9.4515515 | J17: =J12/J15 -> 9.3040903 | ... O17: =O12/O15 -> 9.3474563
B18: MRR por Gestor | C18: =C11/C15 -> 31666.667 | D18: =D11/D15 -> 27347.222 | E18: =E11/E15 -> 26734.079 | F18: =F11/F15 -> 26111.611 | G18: =G11/G15 -> 27061.566 | H18: =H11/H15 -> 26596.215 | I18: =I11/I15 -> 27345.412 | J18: =J11/J15 -> 27025.947 | ... O18: =O11/O15 -> 27529.368
B19: CSV | D19: =(D24+D64)/D11 -> 0.20243779 | E19: =(E24+E64)/E11 -> 0.21045482 | F19: =(F24+F64)/F11 -> 0.21618735 | G19: =(G24+G64)/G11 -> 0.22615099 | H19: =(H24+H64)/H11 -> 0.2307883 | I19: =(I24+I64)/I11 -> 0.22794805 | J19: =(J24+J64)/J11 -> 0.24034142 | K19: =(K24+K64)/K11 -> 0.2469581 | ... O19: =(O24+O64)/O11 -> 0.26502606
C21: Gestor de Performance
C22: Trimestre | D22: 1 Trimestre | G22: 2 Trimestre | J22: 3 Trimestre | M22: 4 Trimestre
C23: Mês | D23: Janeiro | E23: Feveiro | F23: Março | G23: Abril | H23: Maio | I23: Junho | J23: Julho | K23: Agosto | L23: Setembro | M23: Outubro | N23: Novembro | O23: Dezembro | P23: =O24/O11 -> 0.19564561
C24: (=) Gestor de Performance | D24: =SUM(D25:D50) -> 71150 | E24: =SUM(E25:E50) -> 77650 | F24: =SUM(F25:F50) -> 83650 | G24: =SUM(G25:G50) -> 89150 | H24: =SUM(H25:H50) -> 95650 | I24: =SUM(I25:I50) -> 97650 | J24: =SUM(J25:J50) -> 108150 | K24: =SUM(K25:K50) -> 110150 | ... O24: =SUM(O25:O50) -> 134650 | P24: =SUM(D24:O24) -> 1240300
C25: (-) Gabriel Taufner | D25: 1500 | E25: 2000 | F25: 2000 | G25: 2000 | H25: 2500 | I25: 2500 | J25: 2500 | K25: 3000 | L25: 3000 | M25: 3000 | N25: 3500 | O25: 3500
C26: (-) Allan Eduardo | D26: 3000 | E26: 3000 | F26: 3000 | G26: 3500 | H26: 3500 | I26: 3500 | J26: 4000 | K26: 4000 | L26: 4000 | M26: 4500 | N26: 4500 | O26: 4500
C27: (-) Victor Matsushita | D27: 3000 | E27: 3000 | F27: 3500 | G27: 3500 | H27: 3500 | I27: 4000 | J27: 4000 | K27: 4000 | L27: 4500 | M27: 4500 | N27: 4500 | O27: 5000
C28: (-) Gustavo Pires | D28: 3500 | E28: 4000 | F28: 4000 | G28: 4000 | H28: 4500 | I28: 4500 | J28: 4500 | K28: 5000 | L28: 5000 | M28: 5000 | N28: 5000 | O28: 5000
C29: (-) Rayan Coutinho | D29: 4250 | E29: 4250 | F29: 4250 | G29: 4750 | H29: 4750 | I29: 4750 | J29: 5250 | K29: 5250 | L29: 5250 | M29: 5250 | N29: 5750 | O29: 5750
C30: (-) Rafael Avila | D30: 5000 | E30: 5000 | F30: 5000 | G30: 5500 | H30: 5500 | I30: 5500 | J30: 6000 | K30: 6000 | L30: 6000 | M30: 6500 | N30: 6500 | O30: 6500
C31: (-) Thiago Martins | D31: 4500 | E31: 5000 | F31: 5000 | G31: 5000 | H31: 5500 | I31: 5500 | J31: 5500 | K31: 6000 | L31: 6000 | M31: 6000 | N31: 6500 | O31: 6500
C32: (-) Lucas Rosseti | D32: 5000 | E32: 5000 | F32: 5000 | G32: 5500 | H32: 5500 | I32: 5500 | J32: 6000 | K32: 6000 | L32: 6000 | M32: 6500 | N32: 6500 | O32: 6500
C33: (-) Thiago Andrey | D33: 5000 | E33: 5000 | F33: 5000 | G33: 5500 | H33: 5500 | I33: 5500 | J33: 6000 | K33: 6000 | L33: 6000 | M33: 6500 | N33: 6500 | O33: 6500
C34: (-) Victor Arpini | D34: 5000 | E34: 5000 | F34: 5000 | G34: 5500 | H34: 5500 | I34: 5500 | J34: 6000 | K34: 6000 | L34: 6000 | M34: 6500 | N34: 6500 | O34: 6500
C35: (-) Bruno Parreira | D35: 4000 | E35: 4000 | F35: 4000 | G35: 4500 | H35: 4500 | I35: 4500 | J35: 5000 | K35: 5000 | L35: 5000 | M35: 5000 | N35: 5000 | O35: 5000
C36: (-) Jônatas Cavalcante | D36: 4000 | E36: 4000 | F36: 4000 | G36: 4500 | H36: 4500 | I36: 4500 | J36: 5000 | K36: 5000 | L36: 5000 | M36: 5000 | N36: 5000 | O36: 5000
... C42: Novo | D42: 5000 | E42: 5000 | F42: 5000 | G42: 5000 | H42: 5000 | I42: 5500 | J42: 5500 | K42: 5500 | L42: 5500 | M42: 6000 | N42: 6000 | O42: 6000
C43: Novo | E43: 5000 | F43: 5000 | G43: 5000 | H43: 5000 | I43: 5000 | J43: 5000 | K43: 5500 | L43: 5500 | M43: 5500 | N43: 5500 | O43: 5500
C44: Novo | F44: 5000 | G44: 5000 | H44: 5000 | I44: 5000 | J44: 5000 | K44: 5000 | L44: 5500 | M44: 5500 | N44: 5500 | O44: 5500
C45: Novo | H45: 5000 | I45: 5000 | J45: 5000 | K45: 5000 | L45: 5000 | M45: 5500 | N45: 5500 | O45: 5500
C46: Novo | J46: 5000 | K46: 5000 | L46: 5000 | M46: 5000 | N46: 5500 | O46: 5500
C47: Novo | L47: 5000 | M47: 5000 | N47: 5000 | O47: 5000
C48: Novo | M48: 5000 | N48: 5000 | O48: 5000
...

Sheet CAC
Q1: =Q10+Q15+Q21+Q26+Q31+Q39+Q44+Q49+Q54+Q59+Q64 -> 99.395273 | R1: =R10+R15+R21+R26+R31+R39+R44+R49+R54+R59+R64 -> 99.395273 | S1: =S10+S15+S21+S26+S31+S39+S44+S49+S54+S59+S64 -> 99.395273 | T1: =T10+T15+T21+T26+T31+T39+T44+T49+T54+T59+T64 -> 113.12409 | U1: =U10+U15+U21+U26+U31+U39+U44+U49+U54+U59+U64 -> 113.12409 | V1: =V10+V15+V21+V26+V31+V39+V44+V49+V54+V59+V64 -> 113.12409 | W1: =W10+W15+W21+W26+W31+W39+W44+W49+W54+W59+W64 -> 126.8529 | X1: =X10+X15+X21+X26+X31+X39+X44+X49+X54+X59+X64 -> 126.8529 | ... AB1: =AB10+AB15+AB21+AB26+AB31+AB39+AB44+AB49+AB54+AB59+AB64 -> 140.58171
B2: CAC | P2: Aquisition Recorrente
B3: Trimestre | C3: 1 Trimestre | F3: 2 Trimestre | I3: 3 Trimestre | L3: 4 Trimestre | P3: Trimestre | Q3: 1 Trimestre | T3: 2 Trimestre | W3: 3 Trimestre | Z3: 4 Trimestre
B4: Mês | C4: Janeiro | D4: Feveiro | E4: Março | F4: Abril | G4: Maio | H4: Junho | I4: Julho | J4: Agosto | K4: Setembro | L4: Outubro | M4: Novembro | N4: Dezembro | P4: Mês | Q4: Janeiro | R4: Feveiro | S4: Março | T4: Abril | U4: Maio | V4: Junho | W4: Julho | X4: Agosto | Y4: Setembro | Z4: Outubro | AA4: Novembro | AB4: Dezembro
B5: Pessoas Totais Commerce (CSV) | C5: =count(C21:C38)+count(C44:C60)+count(C66:C71)+count(C77:C86) -> 27 | D5: =count(D21:D38)+count(D44:D60)+count(D66:D71)+count(D77:D86) -> 28 | E5: =count(E21:E38)+count(E44:E60)+count(E66:E71)+count(E77:E86) -> 30 | F5: =count(F21:F38)+count(F44:F60)+count(F66:F71)+count(F77:F86) -> 31 | G5: =count(G21:G38)+count(G44:G60)+count(G66:G71)+count(G77:G86) -> 31 | H5: =count(H21:H38)+count(H44:H60)+count(H66:H71)+count(H77:H86) -> 31 | I5: =count(I21:I38)+count(I44:I60)+count(I66:I71)+count(I77:I86) -> 31 | J5: =count(J21:J38)+count(J44:J60)+count(J66:J71)+count(J77:J86) -> 32 | ... N5: =count(N21:N38)+count(N44:N60)+count(N66:N71)+count(N77:N86) -> 35
B6: (=) CAC | C6: =SUM(C7:C15) -> 285217.02 | D6: =SUM(D7:D15) -> 288717.02 | E6: =SUM(E7:E15) -> 314717.02 | F6: =SUM(F7:F15) -> 332957.07 | G6: =SUM(G7:G15) -> 417957.07 | H6: =SUM(H7:H15) -> 357957.07 | I6: =SUM(I7:I15) -> 442197.13 | J6: =SUM(J7:J15) -> 360197.13 | ... N6: =SUM(N7:N15) -> 417437.19 | O6: =sum(C6:N6) -> 4376925.2 | P6: Meta de Vendas MRR | Q6: 200000 | R6: 200000 | S6: 200000 | T6: 220000 | U6: 220000 | V6: 220000 | W6: 240000 | X6: 240000 | Y6: 240000 | Z6: 260000 | AA6: 260000 | AB6: 260000
B7: (-) Pré Vendas | C7: =C21 -> 26850 | D7: =D21 -> 26850 | E7: =E21 -> 32850 | F7: =F21 -> 33850 | G7: =G21 -> 33850 | H7: =H21 -> 33850 | I7: =I21 -> 34850 | J7: =J21 -> 37850 | ... N7: =N21 -> 46850 | P7: % Performance | Q7: 0.3 | R7: 0.3 | S7: 0.3 | T7: 0.3 | U7: 0.3 | V7: 0.3 | W7: 0.3 | X7: 0.3 | Y7: 0.3 | Z7: 0.3 | AA7: 0.3 | AB7: 0.3
B8: (-) Vendas | C8: =C43 -> 32200 | D8: =D43 -> 35700 | E8: =E43 -> 35700 | F8: =F43 -> 39200 | G8: =G43 -> 39200 | H8: =H43 -> 39200 | I8: =I43 -> 39200 | J8: =J43 -> 39200 | ... N8: =N43 -> 39200 | P8: MRR Performance | Q8: =Q6*Q7 -> 60000 | R8: =R6*R7 -> 60000 | S8: =S6*S7 -> 60000 | T8: =T6*T7 -> 66000 | U8: =U6*U7 -> 66000 | V8: =V6*V7 -> 66000 | W8: =W6*W7 -> 72000 | X8: =X6*X7 -> 72000 | ... AB8: =AB6*AB7 -> 78000
B9: (-) Gerencia | C9: =C65 -> 18000 | D9: =D65 -> 18000 | E9: =E65 -> 18000 | F9: =F65 -> 21000 | G9: =G65 -> 21000 | H9: =H65 -> 21000 | I9: =I65 -> 22000 | J9: =J65 -> 22000 | ... N9: =N65 -> 22000 | P9: AOV Performance | Q9: 3000 | R9: 3000 | S9: 3000 | T9: 3000 | U9: 3000 | V9: 3000 | W9: 3000 | X9: 3000 | Y9: 3000 | Z9: 3000 | AA9: 3000 | AB9: 3000
B10: (-) Comissões | C10: =(Q6*0.125)+(Q35*0.1)+(50*Q69) -> 59167.016 | D10: =(R6*0.125)+(R35*0.1)+(50*R69) -> 59167.016 | E10: =(S6*0.125)+(S35*0.1)+(50*S69) -> 59167.016 | F10: =(T6*0.125)+(T35*0.1)+(50*T69) -> 67907.073 | G10: =(U6*0.125)+(U35*0.1)+(50*U69) -> 67907.073 | H10: =(V6*0.125)+(V35*0.1)+(50*V69) -> 67907.073 | I10: =(W6*0.125)+(W35*0.1)+(50*W69) -> 76647.13 | J10: =(X6*0.125)+(X35*0.1)+(50*X69) -> 76647.13 | ... N10: =(AB6*0.125)+(AB35*0.1)+(50*AB69) -> 85387.187 | P10: Contratos Performance | Q10: =Q8/Q9 -> 20 | R10: =R8/R9 -> 20 | S10: =S8/S9 -> 20 | T10: =T8/T9 -> 22 | U10: =U8/U9 -> 22 | V10: =V8/V9 -> 22 | W10: =W8/W9 -> 24 | X10: =X8/X9 -> 24 | ... AB10: =AB8/AB9 -> 26
B11: (-) Growth | C11: =C76 -> 26500 | D11: =D76 -> 26500 | E11: =E76 -> 26500 | F11: =F76 -> 28500 | G11: =G76 -> 28500 | H11: =H76 -> 28500 | I11: =I76 -> 32000 | J11: =J76 -> 32000 | ... N11: =N76 -> 34000
B12: (-) ADs | C12: 100000 | D12: 100000 | E12: 100000 | F12: 110000 | G12: 110000 | H12: 110000 | I12: 120000 | J12: 120000 | K12: 120000 | L12: 130000 | M12: 130000 | N12: 130000 | P12: % Creators | Q12: 0.25 | R12: 0.25 | S12: 0.25 | T12: 0.25 | U12: 0.25 | V12: 0.25 | W12: 0.25 | X12: 0.25 | Y12: 0.25 | Z12: 0.25 | AA12: 0.25 | AB12: 0.25
B13: (-) Eventos | C13: 5000 | D13: 5000 | E13: 25000 | F13: 15000 | G13: 100000 | H13: 40000 | I13: 100000 | J13: 15000 | K13: 25000 | L13: 20000 | M13: 5000 | N13: 25000 | P13: MRR Creators | Q13: =Q6*Q12 -> 50000 | R13: =R6*R12 -> 50000 | S13: =S6*S12 -> 50000 | T13: =T6*T12 -> 55000 | U13: =U6*U12 -> 55000 | V13: =V6*V12 -> 55000 | W13: =W6*W12 -> 60000 | X13: =X6*X12 -> 60000 | ... AB13: =AB6*AB12 -> 65000
B14: (-) Brindes | C14: 12500 | D14: 12500 | E14: 12500 | F14: 12500 | G14: 12500 | H14: 12500 | I14: 12500 | J14: 12500 | K14: 12500 | L14: 12500 | M14: 30000 | N14: 30000 | P14: AOV Creators | Q14: 5000 | R14: 5000 | S14: 5000 | T14: 5000 | U14: 5000 | V14: 5000 | W14: 5000 | X14: 5000 | Y14: 5000 | Z14: 5000 | AA14: 5000 | AB14: 5000
B15: (-) Viagens | C15: 5000 | D15: 5000 | E15: 5000 | F15: 5000 | G15: 5000 | H15: 5000 | I15: 5000 | J15: 5000 | K15: 5000 | L15: 5000 | M15: 5000 | N15: 5000 | P15: Contratos Creators | Q15: =Q13/Q14 -> 10 | R15: =R13/R14 -> 10 | S15: =S13/S14 -> 10 | T15: =T13/T14 -> 11 | U15: =U13/U14 -> 11 | V15: =V13/V14 -> 11 | W15: =W13/W14 -> 12 | X15: =X13/X14 -> 12 | ... AB15: =AB13/AB14 -> 13
C16: =C6/Q1 -> 2869.5229 | D16: =D6/R1 -> 2904.7359 | E16: =E6/S1 -> 3166.3177 | F16: =F6/T1 -> 2943.2907 | G16: =G6/U1 -> 3694.678 | H16: =H6/V1 -> 3164.287 | I16: =I6/W1 -> 3485.9048 | J16: =J6/X1 -> 2839.4868 | ... N16: =N6/AB1 -> 2969.3563
C17: =C12/Q1 -> 1006.0841 | D17: =D12/R1 -> 1006.0841 | E17: =E12/S1 -> 1006.0841 | F17: =F12/T1 -> 972.38355 | G17: =G12/U1 -> 972.38355 | H17: =H12/V1 -> 972.38355 | I17: =I12/W1 -> 945.9776 | J17: =J12/X1 -> 945.9776 | ... N17: =N12/AB1 -> 924.7291
B18: PRÉ VENDAS | P18: % Social | Q18: 0.2 | R18: 0.2 | S18: 0.2 | T18: 0.2 | U18: 0.2 | V18: 0.2 | W18: 0.2 | X18: 0.2 | Y18: 0.2 | Z18: 0.2 | AA18: 0.2 | AB18: 0.2
B19: Trimestre | C19: 1 Trimestre | F19: 2 Trimestre | I19: 3 Trimestre | L19: 4 Trimestre | P19: MRR Social | Q19: =Q6*Q18 -> 40000 | R19: =R6*R18 -> 40000 | S19: =S6*S18 -> 40000 | T19: =T6*T18 -> 44000 | U19: =U6*U18 -> 44000 | V19: =V6*V18 -> 44000 | W19: =W6*W18 -> 48000 | X19: =X6*X18 -> 48000 | ... AB19: =AB6*AB18 -> 52000
B20: Mês | C20: Janeiro | D20: Feveiro | E20: Março | F20: Abril | G20: Maio | H20: Junho | I20: Julho | J20: Agosto | K20: Setembro | L20: Outubro | M20: Novembro | N20: Dezembro | P20: AOV Social | Q20: 2300 | R20: 2300 | S20: 2300 | T20: 2300 | U20: 2300 | V20: 2300 | W20: 2300 | X20: 2300 | Y20: 2300 | Z20: 2300 | AA20: 2300 | AB20: 2300
B21: (=) Pré Vendas | C21: =SUM(C22:C38) -> 26850 | D21: =SUM(D22:D38) -> 26850 | E21: =SUM(E22:E38) -> 32850 | F21: =SUM(F22:F38) -> 33850 | G21: =SUM(G22:G38) -> 33850 | H21: =SUM(H22:H38) -> 33850 | I21: =SUM(I22:I38) -> 34850 | J21: =SUM(J22:J38) -> 37850 | ... N21: =SUM(N22:N38) -> 46850 | P21: Contratos Social | Q21: =Q19/Q20 -> 17.391304 | R21: =R19/R20 -> 17.391304 | S21: =S19/S20 -> 17.391304 | T21: =T19/T20 -> 19.130435 | U21: =U19/U20 -> 19.130435 | V21: =V19/V20 -> 19.130435 | W21: =W19/W20 -> 20.869565 | X21: =X19/X20 -> 20.869565 | ... AB21: =AB19/AB20 -> 22.608696
B22: Guilherme Cassemiro | C22: 3850 | D22: 3850 | E22: 3850 | F22: 3850 | G22: 3850 | H22: 3850 | I22: 3850 | J22: 3850 | K22: 3850 | L22: 3850 | M22: 3850 | N22: 3850
B23: Lenize Pretti | C23: 3000 | D23: 3000 | E23: 3000 | F23: 3000 | G23: 3000 | H23: 3000 | I23: 3000 | J23: 3000 | K23: 3000 | L23: 3000 | M23: 3000 | N23: 3000 | P23: % Gestão de Comunidade | Q23: 0.15 | R23: 0.15 | S23: 0.15 | T23: 0.15 | U23: 0.15 | V23: 0.15 | W23: 0.15 | X23: 0.15 | Y23: 0.15 | Z23: 0.15 | AA23: 0.15 | AB23: 0.15
B24: Eduarda Grippa | C24: 3000 | D24: 3000 | E24: 3000 | F24: 3500 | G24: 3500 | H24: 3500 | I24: 3500 | J24: 3500 | K24: 3500 | L24: 3500 | M24: 3500 | N24: 3500 | P24: MRR Gestão de Comunidade | Q24: =Q6*Q23 -> 30000 | R24: =R6*R23 -> 30000 | S24: =S6*S23 -> 30000 | T24: =T6*T23 -> 33000 | U24: =U6*U23 -> 33000 | V24: =V6*V23 -> 33000 | W24: =W6*W23 -> 36000 | X24: =X6*X23 -> 36000 | ... AB24: =AB6*AB23 -> 39000
B25: Kaike | C25: 3000 | D25: 3000 | E25: 3000 | F25: 3000 | G25: 3000 | H25: 3000 | I25: 3000 | J25: 3000 | K25: 3000 | L25: 3000 | M25: 3000 | N25: 3000 | P25: AOV Gestão de Comunidade | Q25: 10000 | R25: 10000 | S25: 10000 | T25: 10000 | U25: 10000 | V25: 10000 | W25: 10000 | X25: 10000 | Y25: 10000 | Z25: 10000 | AA25: 10000 | AB25: 10000
B26: Isabella | C26: 3000 | D26: 3000 | E26: 3000 | F26: 3500 | G26: 3500 | H26: 3500 | I26: 3500 | J26: 3500 | K26: 3500 | L26: 3500 | M26: 3500 | N26: 3500 | P26: Contratos Gestão de Comunidade | Q26: =Q24/Q25 -> 3 | R26: =R24/R25 -> 3 | S26: =S24/S25 -> 3 | T26: =T24/T25 -> 3.3 | U26: =U24/U25 -> 3.3 | V26: =V24/V25 -> 3.3 | W26: =W24/W25 -> 3.6 | X26: =X24/X25 -> 3.6 | ... AB26: =AB24/AB25 -> 3.9
B27: Fabiely | C27: 3000 | D27: 3000 | E27: 3000 | F27: 3000 | G27: 3000 | H27: 3000 | I27: 3000 | J27: 3000 | K27: 3000 | L27: 3000 | M27: 3000 | N27: 3000
B28: Alanna Oliveira | C28: 3000 | D28: 3000 | E28: 3000 | F28: 3000 | G28: 3000 | H28: 3000 | I28: 3500 | J28: 3500 | K28: 3500 | L28: 3500 | M28: 3500 | N28: 3500 | P28: % Others | Q28: 0.1 | R28: 0.1 | S28: 0.1 | T28: 0.1 | U28: 0.1 | V28: 0.1 | W28: 0.1 | X28: 0.1 | Y28: 0.1 | Z28: 0.1 | AA28: 0.1 | AB28: 0.1
B29: Nova contratação 1 | C29: 2000 | D29: 2000 | E29: 2000 | F29: 2000 | G29: 2000 | H29: 2000 | I29: 2500 | J29: 2500 | K29: 2500 | L29: 2500 | M29: 2500 | N29: 2500 | P29: MRR Others | Q29: =Q6*Q28 -> 20000 | R29: =R6*R28 -> 20000 | S29: =S6*S28 -> 20000 | T29: =T6*T28 -> 22000 | U29: =U6*U28 -> 22000 | V29: =V6*V28 -> 22000 | W29: =W6*W28 -> 24000 | X29: =X6*X28 -> 24000 | ... AB29: =AB6*AB28 -> 26000
B30: Nova contratação 2 | C30: 3000 | D30: 3000 | E30: 3000 | F30: 3000 | G30: 3000 | H30: 3000 | I30: 3000 | J30: 3000 | K30: 3000 | L30: 3000 | M30: 3000 | N30: 3000 | P30: AOV Others | Q30: 1800 | R30: 1800 | S30: 1800 | T30: 1800 | U30: 1800 | V30: 1800 | W30: 1800 | X30: 1800 | Y30: 1800 | Z30: 1800 | AA30: 1800 | AB30: 1800
B31: Nova contratação 3 | E31: 3000 | F31: 3000 | G31: 3000 | H31: 3000 | I31: 3000 | J31: 3000 | K31: 3000 | L31: 3000 | M31: 3000 | N31: 3000 | P31: Contratos Others | Q31: =Q29/Q30 -> 11.111111 | R31: =R29/R30 -> 11.111111 | S31: =S29/S30 -> 11.111111 | T31: =T29/T30 -> 12.222222 | U31: =U29/U30 -> 12.222222 | V31: =V29/V30 -> 12.222222 | W31: =W29/W30 -> 13.333333 | X31: =X29/X30 -> 13.333333 | ... AB31: =AB29/AB30 -> 14.444444
B32: Nova contratação 4 | E32: 3000 | F32: 3000 | G32: 3000 | H32: 3000 | I32: 3000 | J32: 3000 | K32: 3000 | L32: 3000 | M32: 3000 | N32: 3000
B33: Nova contratação 5 | J33: 3000 | K33: 3000 | L33: 3000 | M33: 3000 | N33: 3000 | P33: Aquisition Pontual
B34: Nova contratação 6 | K34: 3000 | L34: 3000 | M34: 3000 | N34: 3000 | P34: Trimestre | Q34: 1 Trimestre | T34: 2 Trimestre | W34: 3 Trimestre | Z34: 4 Trimestre
B35: Nova contratação 7 (backup turnover) | L35: 3000 | M35: 3000 | N35: 3000 | P35: Meta de Vendas Pontual | Q35: 250000 | R35: 250000 | S35: 250000 | T35: 300000 | U35: 300000 | V35: 300000 | W35: 350000 | X35: 350000 | Y35: 350000 | Z35: 400000 | AA35: 400000 | AB35: 400000
B36: Nova contratação 8 (backup turnover) | N36: 3000 | P36: % E-commerce | Q36: 0.42 | R36: 0.42 | S36: 0.42 | T36: 0.42 | U36: 0.42 | V36: 0.42 | W36: 0.42 | X36: 0.42 | Y36: 0.42 | Z36: 0.42 | AA36: 0.42 | AB36: 0.42
B37: Nova contratação 9 | P37: Pontual e-commerce | Q37: =Q35*Q36 -> 105000 | R37: =R35*R36 -> 105000 | S37: =S35*S36 -> 105000 | T37: =T35*T36 -> 126000 | U37: =U35*U36 -> 126000 | V37: =V35*V36 -> 126000 | W37: =W35*W36 -> 147000 | X37: =X35*X36 -> 147000 | ... AB37: =AB35*AB36 -> 168000
B38: Nova contratação 10 | P38: AOV E-commerce | Q38: 15000 | R38: 15000 | S38: 15000 | T38: 15000 | U38: 15000 | V38: 15000 | W38: 15000 | X38: 15000 | Y38: 15000 | Z38: 15000 | AA38: 15000 | AB38: 15000
P39: Contratos E-commerce | Q39: =Q37/Q38 -> 7 | R39: =R37/R38 -> 7 | S39: =S37/S38 -> 7 | T39: =T37/T38 -> 8.4 | U39: =U37/U38 -> 8.4 | V39: =V37/V38 -> 8.4 | W39: =W37/W38 -> 9.8 | X39: =X37/X38 -> 9.8 | ... AB39: =AB37/AB38 -> 11.2
B40: Vendas
...

Sheet Revenue
B2: Receita Recorrente
B3: Trimestre | C3: Bookado | D3: 1 Trimestre | G3: 2 Trimestre | J3: 3 Trimestre | M3: 4 Trimestre
B4: Mês | C4: Dezembro | D4: Janeiro | E4: Feveiro | F4: Março | G4: Abril | H4: Maio | I4: Junho | J4: Julho | K4: Agosto | L4: Setembro | M4: Outubro | N4: Novembro | O4: Dezembro
B5: MRR Ativo | C5: =C7+C12+C17+C27+C22 -> 1050000 | D5: =D7+D12+D17+D27+D22 -> 1155500 | E5: =E7+E12+E17+E27+E22 -> 1251505 | F5: =F7+F12+F17+F27+F22 -> 1338869.6 | G5: =G7+G12+G17+G27+G22 -> 1438371.3 | H5: =H7+H12+H17+H27+H22 -> 1528917.9 | I5: =I7+I12+I17+I27+I22 -> 1611315.3 | J5: =J7+J12+J17+J27+J22 -> 1706296.9 | ... O5: =O7+O12+O17+O27+O22 -> 2122127.1
B7: MRR Performance | C7: 475000 | D7: =((1-C10)*C7)+CAC!Q8 -> 492250 | E7: =((1-D10)*D7)+CAC!R8 -> 507947.5 | F7: =((1-E10)*E7)+CAC!S8 -> 522232.22 | G7: =((1-F10)*F7)+CAC!T8 -> 541231.32 | H7: =((1-G10)*G7)+CAC!U8 -> 558520.51 | I7: =((1-H10)*H7)+CAC!V8 -> 574253.66 | J7: =((1-I10)*I7)+CAC!W8 -> 594570.83 | K7: =((1-J10)*J7)+CAC!X8 -> 613059.46 | ... O7: =((1-N10)*N7)+CAC!AB8 -> 688234.19
B8: AOV Performance | C8: =C7/C9 -> 2794.1176 | D8: =((C8*C9)+(CAC!Q9*CAC!Q10))/(CAC!Q10+C9) -> 2815.7895 | E8: =((D8*D9)+(CAC!R9*CAC!R10))/(CAC!R10+D9) -> 2834.7005 | F8: =((E8*E9)+(CAC!S9*CAC!S10))/(CAC!S10+E9) -> 2851.2978 | G8: =((F8*F9)+(CAC!T9*CAC!T10))/(CAC!T10+F9) -> 2867.2439 | H8: =((G8*G9)+(CAC!U9*CAC!U10))/(CAC!U10+G9) -> 2881.1013 | I8: =((H8*H9)+(CAC!V9*CAC!V10))/(CAC!V10+H9) -> 2893.2194 | J8: =((I8*I9)+(CAC!W9*CAC!W10))/(CAC!W10+I9) -> 2904.7382 | K8: =((J8*J9)+(CAC!X9*CAC!X10))/(CAC!X10+J9) -> 2914.7355 | ... O8: =((N8*N9)+(CAC!AB9*CAC!AB10))/(CAC!AB10+N9) -> 2945.1186
B9: Contratos Performance | C9: 170 | D9: =D7/D8 -> 174.81776 | E9: =E7/E8 -> 179.18912 | F9: =F7/F8 -> 183.15598 | G9: =G7/G8 -> 188.76361 | H9: =H7/H8 -> 193.8566 | I9: =I7/I8 -> 198.48258 | J9: =J7/J8 -> 204.68999 | K9: =K7/K8 -> 210.33107 | ... O9: =O7/O8 -> 233.68641 | Q9: Churn
B10: Churn Performance | C10: =$Q$10 -> 0.09 | D10: =$Q$10 -> 0.09 | E10: =$Q$10 -> 0.09 | F10: =$Q$10 -> 0.09 | G10: =$Q$10 -> 0.09 | H10: =$Q$10 -> 0.09 | I10: =$Q$10 -> 0.09 | J10: =$Q$10 -> 0.09 | ... O10: =$Q$10 -> 0.09 | Q10: 0.09
B12: MRR Creators | C12: 200000 | D12: =((1-C15)*C12)+CAC!Q13 -> 232000 | E12: =((1-D15)*D12)+CAC!R13 -> 261120 | F12: =((1-E15)*E12)+CAC!S13 -> 287619.2 | G12: =((1-F15)*F12)+CAC!T13 -> 316733.47 | H12: =((1-G15)*G12)+CAC!U13 -> 343227.46 | I12: =((1-H15)*H12)+CAC!V13 -> 367336.99 | J12: =((1-I15)*I12)+CAC!W13 -> 394276.66 | K12: =((1-J15)*J12)+CAC!X13 -> 418791.76 | ... O12: =((1-N15)*N12)+CAC!AB13 -> 510377.05
B13: AOV Creators | C13: =C12/C14 -> 4255.3191 | D13: =((C13*C14)+(CAC!Q14*CAC!Q15))/(CAC!Q15+C14) -> 4385.9649 | E13: =((D13*D14)+(CAC!R14*CAC!R15))/(CAC!R15+D14) -> 4483.592 | F13: =((E13*E14)+(CAC!S14*CAC!S15))/(CAC!S15+E14) -> 4559.2683 | G13: =((F13*F14)+(CAC!T14*CAC!T15))/(CAC!T15+F14) -> 4624.7078 | H13: =((G13*G14)+(CAC!U14*CAC!U15))/(CAC!U15+G14) -> 4676.6433 | I13: =((H13*H14)+(CAC!V14*CAC!V15))/(CAC!V15+H14) -> 4718.791 | J13: =((I13*I14)+(CAC!W14*CAC!W15))/(CAC!W15+I14) -> 4756.35 | K13: =((J13*J14)+(CAC!X14*CAC!X15))/(CAC!X15+J14) -> 4787.161 | ... O13: =((N13*N14)+(CAC!AB14*CAC!AB15))/(CAC!AB15+N14) -> 4872.0565
B14: Contratos Creators | C14: 47 | D14: =D12/D13 -> 52.896 | E14: =E12/E13 -> 58.23902 | F14: =F12/F13 -> 63.084508 | G14: =G12/G13 -> 68.48724 | H14: =H12/H13 -> 73.39184 | I14: =I12/I13 -> 77.845572 | J14: =J12/J13 -> 82.894795 | K14: =K12/K13 -> 87.482281 | ... O14: =O12/O13 -> 104.75598 | Q14: Churn
B15: Churn Creators | C15: =$Q$15 -> 0.09 | D15: =$Q$15 -> 0.09 | E15: =$Q$15 -> 0.09 | F15: =$Q$15 -> 0.09 | G15: =$Q$15 -> 0.09 | H15: =$Q$15 -> 0.09 | I15: =$Q$15 -> 0.09 | J15: =$Q$15 -> 0.09 | ... O15: =$Q$15 -> 0.09 | Q15: 0.09
B17: MRR Social | C17: 210000 | D17: =((1-C20)*C17)+CAC!Q19 -> 231100 | E17: =((1-E20)*D17)+CAC!R19 -> 250301 | F17: =((1-F20)*E17)+CAC!S19 -> 267773.91 | G17: =((1-G20)*F17)+CAC!T19 -> 287674.26 | H17: =((1-H20)*G17)+CAC!U19 -> 305783.57 | I17: =((1-I20)*H17)+CAC!V19 -> 322263.05 | J17: =((1-J20)*I17)+CAC!W19 -> 341259.38 | K17: =((1-K20)*J17)+CAC!X19 -> 358546.03 | L17: =((1-L20)*K17)+CAC!Y19 -> 374276.89 | ... O17: =((1-O20)*N17)+CAC!AB19 -> 424425.41
B18: AOV Social | C18: =C17/C19 -> 2258.0645 | D18: =((C18*C19)+(CAC!Q20*CAC!Q21))/(CAC!Q21+C19) -> 2264.6711 | E18: =((D18*D19)+(CAC!R20*CAC!R21))/(CAC!R21+D19) -> 2269.8154 | F18: =((E18*E19)+(CAC!S20*CAC!S21))/(CAC!S21+E19) -> 2273.9273 | G18: =((F18*F19)+(CAC!T20*CAC!T21))/(CAC!T21+F19) -> 2277.571 | H18: =((G18*G19)+(CAC!U20*CAC!U21))/(CAC!U21+G19) -> 2280.5213 | I18: =((H18*H19)+(CAC!V20*CAC!V21))/(CAC!V21+H19) -> 2282.9534 | J18: =((I18*I19)+(CAC!W20*CAC!W21))/(CAC!W21+I19) -> 2285.149 | K18: =((J18*J19)+(CAC!X20*CAC!X21))/(CAC!X21+J19) -> 2286.9699 | ... O18: =((N18*N19)+(CAC!AB20*CAC!AB21))/(CAC!AB21+N19) -> 2292.0771
B19: Contratos Social | C19: 93 | D19: =D17/D18 -> 102.04572 | E19: =E17/E18 -> 110.27373 | F19: =F17/F18 -> 117.75834 | G19: =G17/G18 -> 126.30748 | H19: =H17/H18 -> 134.08495 | I19: =I17/I18 -> 141.16059 | J19: =J17/J18 -> 149.33791 | K19: =K17/K18 -> 156.77777 | ... O19: =O17/O18 -> 185.17065 | Q19: Churn
B20: Churn Social | C20: =$Q$20 -> 0.09 | D20: =$Q$20 -> 0.09 | E20: =$Q$20 -> 0.09 | F20: =$Q$20 -> 0.09 | G20: =$Q$20 -> 0.09 | H20: =$Q$20 -> 0.09 | I20: =$Q$20 -> 0.09 | J20: =$Q$20 -> 0.09 | ... O20: =$Q$20 -> 0.09 | Q20: 0.09
B22: MRR Gestão de Comunidade | C22: 60000 | D22: =(((1-C25)*C22))+CAC!Q24 -> 84600 | E22: =(((1-D25)*D22))+CAC!R24 -> 106986 | F22: =(((1-E25)*E22))+CAC!S24 -> 127357.26 | G22: =(((1-F25)*F22))+CAC!T24 -> 148895.11 | H22: =(((1-G25)*G22))+CAC!U24 -> 168494.55 | I22: =(((1-H25)*H22))+CAC!V24 -> 186330.04 | J22: =(((1-I25)*I22))+CAC!W24 -> 205560.33 | K22: =(((1-J25)*J22))+CAC!X24 -> 223059.9 | ... O22: =(((1-N25)*N22))+CAC!AB24 -> 286877.7
B23: AOV Gestão de Comunidade | C23: =C22/C24 -> 5454.5455 | D23: =((C23*C24)+(CAC!Q26*CAC!Q25))/(CAC!Q26+C24) -> 6428.5714 | E23: =((D23*D24)+(CAC!R26*CAC!R25))/(CAC!R26+D24) -> 7091.5842 | F23: =((E23*E24)+(CAC!S26*CAC!S25))/(CAC!S26+E24) -> 7574.0063 | G23: =((F23*F24)+(CAC!T26*CAC!T25))/(CAC!T26+F24) -> 7972.0059 | H23: =((G23*G24)+(CAC!U26*CAC!U25))/(CAC!U26+G24) -> 8276.5199 | I23: =((H23*H24)+(CAC!V26*CAC!V25))/(CAC!V26+H24) -> 8516.9228 | J23: =((I23*I24)+(CAC!W26*CAC!W25))/(CAC!W26+I24) -> 8726.4823 | K23: =((J23*J24)+(CAC!X26*CAC!X25))/(CAC!X26+J24) -> 8895.3097 | ... O23: =((N23*N24)+(CAC!AB26*CAC!AB25))/(CAC!AB26+N24) -> 9347.533
B24: Contratos Gestão de Comunidade | C24: 11 | D24: =D22/D23 -> 13.16 | E24: =E22/E23 -> 15.086333 | F24: =F22/F23 -> 16.815045 | G24: =G22/G23 -> 18.677245 | H24: =H22/H23 -> 20.358139 | I24: =I22/I23 -> 21.877624 | J24: =J22/J23 -> 23.555922 | K24: =K22/K23 -> 25.076126 | ... O24: =O22/O23 -> 30.690204 | Q24: Churn
B25: Churn Gestão de Comunidade | C25: =$Q$25 -> 0.09 | D25: =$Q$25 -> 0.09 | E25: =$Q$25 -> 0.09 | F25: =$Q$25 -> 0.09 | G25: =$Q$25 -> 0.09 | H25: =$Q$25 -> 0.09 | I25: =$Q$25 -> 0.09 | J25: =$Q$25 -> 0.09 | ... O25: =$Q$25 -> 0.09 | Q25: 0.09
B27: MRR Others | C27: 105000 | D27: =((1-C30)*C27)+CAC!Q29 -> 115550 | E27: =((1-D30)*D27)+CAC!R29 -> 125150.5 | F27: =((1-E30)*E27)+CAC!S29 -> 133886.95 | G27: =((1-F30)*F27)+CAC!T29 -> 143837.13 | H27: =((1-G30)*G27)+CAC!U29 -> 152891.79 | I27: =((1-H30)*H27)+CAC!V29 -> 161131.53 | J27: =((1-I30)*I27)+CAC!W29 -> 170629.69 | K27: =((1-J30)*J27)+CAC!X29 -> 179273.02 | ... O27: =((1-N30)*N27)+CAC!AB29 -> 212212.71
B28: AOV Others | C28: =C27/C29 -> 1346.1538 | D28: =((C28*C29)+(CAC!Q30*CAC!Q31))/(CAC!Q31+C29) -> 1402.7431 | E28: =((D28*D29)+(CAC!R30*CAC!R31))/(CAC!R31+D29) -> 1449.9587 | F28: =((E28*E29)+(CAC!S30*CAC!S31))/(CAC!S31+E29) -> 1489.8804 | G28: =((F28*F29)+(CAC!T30*CAC!T31))/(CAC!T31+F29) -> 1527.0093 | H28: =((G28*G29)+(CAC!U30*CAC!U31))/(CAC!U31+G29) -> 1558.3627 | I28: =((H28*H29)+(CAC!V30*CAC!V31))/(CAC!V31+H29) -> 1585.1303 | J28: =((I28*I29)+(CAC!W30*CAC!W31))/(CAC!W31+I29) -> 1610.0459 | K28: =((J28*J29)+(CAC!X30*CAC!X31))/(CAC!X31+J29) -> 1631.2737 | ... O28: =((N28*N29)+(CAC!AB30*CAC!AB31))/(CAC!AB31+N29) -> 1693.7164
B29: Contratos Others | C29: 78 | D29: =D27/D28 -> 82.374311 | E29: =E27/E28 -> 86.313149 | F29: =F27/F28 -> 89.864227 | G29: =G27/G28 -> 94.195321 | H29: =H27/H28 -> 98.110529 | I29: =I27/I28 -> 101.65191 | J29: =J27/J28 -> 105.97815 | K29: =K27/K28 -> 109.89757 | ... O29: =O27/O28 -> 125.29412 | Q29: Churn
B30: Churn Others | C30: =$Q$30 -> 0.09 | D30: =$Q$30 -> 0.09 | E30: =$Q$30 -> 0.09 | F30: =$Q$30 -> 0.09 | G30: =$Q$30 -> 0.09 | H30: =$Q$30 -> 0.09 | I30: =$Q$30 -> 0.09 | J30: =$Q$30 -> 0.09 | ... O30: =$Q$30 -> 0.09 | Q30: 0.09
B32: Churn Total | C32: =(Revenue!C7*Revenue!C10)+(Revenue!C12*Revenue!C15)+(Revenue!C17*Revenue!C20)+(Revenue!C22*Revenue!C25)+(Revenue!C27*Revenue!C30) -> 94500 | D32: =(Revenue!D7*Revenue!D10)+(Revenue!D12*Revenue!D15)+(Revenue!D17*Revenue!D20)+(Revenue!D22*Revenue!D25)+(Revenue!D27*Revenue!D30) -> 103995 | E32: =(Revenue!E7*Revenue!E10)+(Revenue!E12*Revenue!E15)+(Revenue!E17*Revenue!E20)+(Revenue!E22*Revenue!E25)+(Revenue!E27*Revenue!E30) -> 112635.45 | F32: =(Revenue!F7*Revenue!F10)+(Revenue!F12*Revenue!F15)+(Revenue!F17*Revenue!F20)+(Revenue!F22*Revenue!F25)+(Revenue!F27*Revenue!F30) -> 120498.26 | G32: =(Revenue!G7*Revenue!G10)+(Revenue!G12*Revenue!G15)+(Revenue!G17*Revenue!G20)+(Revenue!G22*Revenue!G25)+(Revenue!G27*Revenue!G30) -> 129453.42 | H32: =(Revenue!H7*Revenue!H10)+(Revenue!H12*Revenue!H15)+(Revenue!H17*Revenue!H20)+(Revenue!H22*Revenue!H25)+(Revenue!H27*Revenue!H30) -> 137602.61 | I32: =(Revenue!I7*Revenue!I10)+(Revenue!I12*Revenue!I15)+(Revenue!I17*Revenue!I20)+(Revenue!I22*Revenue!I25)+(Revenue!I27*Revenue!I30) -> 145018.37 | J32: =(Revenue!J7*Revenue!J10)+(Revenue!J12*Revenue!J15)+(Revenue!J17*Revenue!J20)+(Revenue!J22*Revenue!J25)+(Revenue!J27*Revenue!J30) -> 153566.72 | ... O32: =(Revenue!O7*Revenue!O10)+(Revenue!O12*Revenue!O15)+(Revenue!O17*Revenue!O20)+(Revenue!O22*Revenue!O25)+(Revenue!O27*Revenue!O30) -> 190991.43
B34: Receita Pontual
B35: Trimestre | C35: Bookado | D35: 1 Trimestre | G35: 2 Trimestre | J35: 3 Trimestre | M35: 4 Trimestre
B36: Mês | C36: Dezembro | D36: Janeiro | E36: Feveiro | F36: Março | G36: Abril | H36: Maio | I36: Junho | J36: Julho | K36: Agosto | L36: Setembro | M36: Outubro | N36: Novembro | O36: Dezembro
B37: Receita Pontual | D37: =(CAC!Q35/3)+150000 -> 233333.33 | E37: =((CAC!Q35/3)+(CAC!R35/3))+100000 -> 266666.67 | F37: =(CAC!R35/3)+(CAC!S35/3)+(CAC!Q35/3) -> 250000 | G37: =(CAC!S35/3)+(CAC!T35/3)+(CAC!R35/3) -> 266666.67 | H37: =(CAC!T35/3)+(CAC!U35/3)+(CAC!S35/3) -> 283333.33 | I37: =(CAC!U35/3)+(CAC!V35/3)+(CAC!T35/3) -> 300000 | J37: =(CAC!V35/3)+(CAC!W35/3)+(CAC!U35/3) -> 316666.67 | K37: =(CAC!W35/3)+(CAC!X35/3)+(CAC!V35/3) -> 333333.33 | L37: =(CAC!X35/3)+(CAC!Y35/3)+(CAC!W35/3) -> 350000 | M37: =(CAC!Y35/3)+(CAC!Z35/3)+(CAC!X35/3) -> 366666.67 | ... O37: =(CAC!AA35/3)+(CAC!AB35/3)+(CAC!Z35/3) -> 400000

Sheet CAPEX e Giro
B2: CAPEX
B3: Trimestre | D3: 1 Trimestre | G3: 2 Trimestre | J3: 3 Trimestre | M3: 4 Trimestre
B4: Mês | C4: Dezembro | D4: Janeiro | E4: Feveiro | F4: Março | G4: Abril | H4: Maio | I4: Junho | J4: Julho | K4: Agosto | L4: Setembro | M4: Outubro | N4: Novembro | O4: Dezembro
B5: (=) CAPEX | D5: =IF(6500*D9>0, 6500*D9, 0) -> 32500 | E5: =IF(6500*E9>0, 6500*E9, 0) -> 32500 | F5: =IF(6500*F9>0, 6500*F9, 0) -> 32500 | G5: =IF(6500*G9>0, 6500*G9, 0) -> 32500 | H5: =IF(6500*H9>0, 6500*H9, 0) -> 32500 | I5: =IF(6500*I9>0, 6500*I9, 0) -> 32500 | J5: =IF(6500*J9>0, 6500*J9, 0) -> 32500 | K5: =IF(6500*K9>0, 6500*K9, 0) -> 32500 | ... O5: =IF(6500*O9>0, 6500*O9, 0) -> 32500
B6: (=) Colaboradores totais | D6: =Overview!C26 -> 126 | E6: =Overview!D26 -> 129 | F6: =Overview!E26 -> 138 | G6: =Overview!F26 -> 143 | H6: =Overview!G26 -> 147 | I6: =Overview!H26 -> 152 | J6: =Overview!I26 -> 159 | K6: =Overview!J26 -> 164 | ... O6: =Overview!N26 -> 180
B7: (=) Computadores totais | D7: 76 | E7: =D7+D9 -> 81 | F7: =E7+E9 -> 86 | G7: =F7+F9 -> 91 | H7: =G7+G9 -> 96 | I7: =H7+H9 -> 101 | J7: =I7+I9 -> 106 | K7: =J7+J9 -> 111 | L7: =K7+K9 -> 116 | ... O7: =N7+N9 -> 131
B8: (=) Computadores a comprar | D8: =D6-D7 -> 50 | E8: =E6-E7 -> 48 | F8: =F6-F7 -> 52 | G8: =G6-G7 -> 52 | H8: =H6-H7 -> 51 | I8: =I6-I7 -> 51 | J8: =J6-J7 -> 53 | K8: =K6-K7 -> 53 | ... O8: =O6-O7 -> 49
B9: (-) Computadores comprados mês | D9: 5 | E9: 5 | F9: 5 | G9: 5 | H9: 5 | I9: 5 | J9: 5 | K9: 5 | L9: 5 | M9: 5 | N9: 5 | O9: 5

Sheet Tributário
B2: 1 Trimestre | E2: Trimestre | F2: 1 Trimestre | I2: 2 Trimestre | L2: 3 Trimestre | O2: 4 Trimestre
B3: % NF Emitida | C3: 0.95 | E3: Mês | F3: Janeiro | G3: Feveiro | H3: Março | I3: Abril | J3: Maio | K3: Junho | L3: Julho | M3: Agosto | N3: Setembro | O3: Outubro | P3: Novembro | Q3: Dezembro
B4: Simples Nacional | C4: 0.16 | E4: Receita Total | F4: =Overview!C4+Overview!C5 -> 1388833.3 | G4: =Overview!D4+Overview!D5 -> 1518171.7 | H4: =Overview!E4+Overview!E5 -> 1588869.6 | I4: =Overview!F4+Overview!F5 -> 1705038 | J4: =Overview!G4+Overview!G5 -> 1812251.2 | K4: =Overview!H4+Overview!H5 -> 1911315.3 | L4: =Overview!I4+Overview!I5 -> 2022963.6 | M4: =Overview!J4+Overview!J5 -> 2126063.5 | ... Q4: =Overview!N4+Overview!N5 -> 2522127.1
B5: ISS | C5: 0.05 | E5: Receita NF | F5: =F4*$C$3 -> 1319391.7 | G5: =G4*$C$3 -> 1442263.1 | H5: =H4*$C$3 -> 1509426.1 | I5: =I4*$C$10 -> 1619786.1 | J5: =J4*$C$10 -> 1721638.6 | K5: =K4*$C$10 -> 1815749.5 | L5: =L4*$C$17 -> 1921815.4 | M5: =M4*$C$17 -> 2019760.3 | N5: =N4*$C$17 -> 2110315.2 | O5: =O4*$C$24 -> 2213145.2 | P5: =P4*$C$24 -> 2308145.5 | Q5: =Q4*$C$24 -> 2396020.7
B6: PIS/COFINS | C6: 0.06 | E6: Receita Bruta Peixoto | F6: =160000/0.92 -> 173913.04 | G6: =160000/0.92 -> 173913.04 | H6: =160000/0.92 -> 173913.04 | I6: =160000/0.92 -> 173913.04 | J6: =160000/0.92 -> 173913.04 | K6: =160000/0.92 -> 173913.04 | L6: =160000/0.92 -> 173913.04 | M6: =160000/0.92 -> 173913.04 | ... Q6: =160000/0.92 -> 173913.04
B7: CSLL + IRPJ | C7: 0.34 | E7: (=) Receita Liquida Peixoto | F7: =F6*(1-Overview!$S$3) -> 163478.26 | G7: =G6*(1-Overview!$S$3) -> 163478.26 | H7: =H6*(1-Overview!$S$3) -> 163478.26 | I7: =I6*(1-Overview!$S$6) -> 163478.26 | J7: =J6*(1-Overview!$S$6) -> 163478.26 | K7: =K6*(1-Overview!$S$6) -> 163478.26 | L7: =L6*(1-Overview!$S$9) -> 163478.26 | M7: =M6*(1-Overview!$S$9) -> 163478.26 | N7: =N6*(1-Overview!$S$9) -> 163478.26 | O7: =O6*(1-Overview!$S$12) -> 163478.26 | P7: =P6*(1-Overview!$S$12) -> 163478.26 | Q7: =Q6*(1-Overview!$S$12) -> 163478.26
E8: Receita Bruta Turbo Partners | F8: =F5-F6 -> 1145478.6 | G8: =G5-G6 -> 1268350 | H8: =H5-H6 -> 1335513 | I8: =I5-I6 -> 1445873 | J8: =J5-J6 -> 1547725.6 | K8: =K5-K6 -> 1641836.5 | L8: =L5-L6 -> 1747902.3 | M8: =M5-M6 -> 1845847.3 | ... Q8: =Q5-Q6 -> 2222107.7
B9: 2 Trimestre | E9: (=) Receita Liquida Turbo | F9: =F8*(1-Overview!$S$3) -> 1076749.9 | G9: =G8*(1-Overview!$S$3) -> 1192249 | H9: =H8*(1-Overview!$S$3) -> 1255382.2 | I9: =I8*(1-Overview!$S$6) -> 1359120.6 | J9: =J8*(1-Overview!$S$6) -> 1454862.1 | K9: =K8*(1-Overview!$S$6) -> 1543326.3 | L9: =L8*(1-Overview!$S$9) -> 1643028.2 | M9: =M8*(1-Overview!$S$9) -> 1735096.4 | N9: =N8*(1-Overview!$S$9) -> 1820218.1 | O9: =O8*(1-Overview!$S$12) -> 1916878.2 | P9: =P8*(1-Overview!$S$12) -> 2006178.5 | Q9: =Q8*(1-Overview!$S$12) -> 2088781.2
B10: % NF Emitida | C10: 0.95
